Workbook

Sheet Концепции и критерии
A1: Фаза 1. Выбор концепции проекта — чёткий коллективный МАИ (метод анализа иерархий Саати)
A3: № | B3: Короткое название | C3: Концепция проекта
A4: 1 | B4: Сплит | C4: Веб-приложение для учёта и разделения общих расходов в группе (поездки, съёмная квартира, мероприятия)
A5: 2 | B5: Репетиторы | C5: Онлайн-платформа поиска репетиторов с расписанием занятий и онлайн-оплатой
A6: 3 | B6: Аудитории | C6: Веб-сервис бронирования учебных аудиторий и переговорных комнат университета
A7: 4 | B7: AR-гид | C7: Мобильное приложение с AR-экскурсиями по историческому центру города
A8: 5 | B8: Рецепты | C8: Мобильное приложение подбора рецептов по имеющимся дома продуктам
A10: № | B10: Критерий | C10: Что оценивается (все критерии — «чем больше, тем лучше»)
A11: K1 | B11: Экономичность | C11: Затраты на разработку, инфраструктуру и сопровождение (чем выше оценка, тем дешевле проект)
A12: K2 | B12: Актуальность | C12: Востребованность продукта у целевой аудитории в данный момент
A13: K3 | B13: Потенциал развития | C13: Возможность масштабирования, добавления функций и монетизации
A14: K4 | B14: Простота реализации | C14: Техническая сложность и время до работающего MVP
A15: K5 | B15: Соответствие компетенциям | C15: Насколько стек технологий и предметная область знакомы команде
A17: № | B17: Эксперт | C17: Роль в оценке
A18: 1 | B18: Александр Ф. | C18: Участник команды, независимая экспертная оценка
A19: 2 | B19: Алексей К. | C19: Участник команды, независимая экспертная оценка
A20: 3 | B20: Александр Л. | C20: Участник команды, независимая экспертная оценка
B22: Обозначения:
C23: исходные данные (оценки экспертов) — можно менять
C24: итоговые результаты расчёта
B26: Значение | C26: Шкала Саати для парных сравнений
B27: 1 | C27: Равная важность
B28: 3 | C28: Умеренное превосходство одного над другим
B29: 5 | C29: Существенное превосходство
B30: 7 | C30: Значительное превосходство
B31: 9 | C31: Очень сильное (абсолютное) превосходство
B32: 2, 4, 6, 8 | C32: Промежуточные значения между соседними суждениями
B33: 1/x | C33: Обратные величины: если i в x раз важнее j, то j в 1/x раз важнее i
B35: Размер матрицы n | C35: Случайный индекс согласованности RI
B36: 3 | C36: 0.58
B37: 4 | C37: 0.9
B38: 5 | C38: 1.12
B39: 6 | C39: 1.24
B40: 7 | C40: 1.32
A42: Матрица считается согласованной, если отношение согласованности ОС = ИС / RI ≤ 0,10; ИС = (λmax − n) / (n − 1).

Sheet Критерии
A1: МАИ: парные сравнения — Критерий
A2: Эксперт заполняет только верхний треугольник (жёлтые ячейки): «во сколько раз строка предпочтительнее столбца». Нижний треугольник — обратные величины.
A4: Эксперт: Александр Ф.
A5: Критерий | B5: Экономичность | C5: Актуальность | D5: Потенциал развития | E5: Простота реализации | F5: Соответствие компетенциям | G5: Ср. геом. строки | H5: Вес w | I5: (A·w)ᵢ | J5: (A·w)ᵢ / wᵢ
A6: Экономичность | B6: 1 | C6: 2 | D6: 2 | E6: 2 | F6: 1 | G6: =GEOMEAN(B6:F6) -> 1.5157166 | H6: =G6/SUM($G$6:$G$10) -> 0.29178026 | I6: =B6*$H$6+C6*$H$7+D6*$H$8+E6*$H$9+F6*$H$10 -> 1.5157166 | J6: =I6/H6 -> 5.1947194
A7: Актуальность | B7: =1/C6 -> 0.5 | C7: 1 | D7: 1 | E7: =1/2 -> 0.5 | F7: 2 | G7: =GEOMEAN(B7:F7) -> 0.87055056 | H7: =G7/SUM($G$6:$G$10) -> 0.16758375 | I7: =B7*$H$6+C7*$H$7+D7*$H$8+E7*$H$9+F7*$H$10 -> 0.93604901 | J7: =I7/H7 -> 5.5855595
A8: Потенциал развития | B8: =1/D6 -> 0.5 | C8: =1/D7 -> 1 | D8: 1 | E8: =1/2 -> 0.5 | F8: =1/2 -> 0.5 | G8: =GEOMEAN(B8:F8) -> 0.65975396 | H8: =G8/SUM($G$6:$G$10) -> 0.12700473 | I8: =B8*$H$6+C8*$H$7+D8*$H$8+E8*$H$9+F8*$H$10 -> 0.64729424 | J8: =I8/H8 -> 5.0966151
A9: Простота реализации | B9: =1/E6 -> 0.5 | C9: =1/E7 -> 2 | D9: =1/E8 -> 2 | E9: 1 | F9: 1 | G9: =GEOMEAN(B9:F9) -> 1.1486984 | H9: =G9/SUM($G$6:$G$10) -> 0.22112808 | I9: =B9*$H$6+C9*$H$7+D9*$H$8+E9*$H$9+F9*$H$10 -> 1.1486984 | J9: =I9/H9 -> 5.1947194
A10: Соответствие компетенциям | B10: =1/F6 -> 1 | C10: =1/F7 -> 0.5 | D10: =1/F8 -> 2 | E10: =1/F9 -> 1 | F10: 1 | G10: =GEOMEAN(B10:F10) -> 1 | H10: =G10/SUM($G$6:$G$10) -> 0.19250318 | I10: =B10*$H$6+C10*$H$7+D10*$H$8+E10*$H$9+F10*$H$10 -> 1.0432129 | J10: =I10/H10 -> 5.4191981
A11: λmax | B11: =AVERAGE(J6:J10) -> 5.2981623
A12: Индекс согласованности ИС | B12: =(B11-5)/(5-1) -> 0.074540581
A13: Отношение согласованности ОС | B13: =B12/'Концепции и критерии'!$C$38 -> 0.06655409 | C13: =IF(B13<=0.1,"согласована (ОС ≤ 10%)","требует пересмотра") -> согласована (ОС ≤ 10%)
A15: Эксперт: Алексей К.
A16: Критерий | B16: Экономичность | C16: Актуальность | D16: Потенциал развития | E16: Простота реализации | F16: Соответствие компетенциям | G16: Ср. геом. строки | H16: Вес w | I16: (A·w)ᵢ | J16: (A·w)ᵢ / wᵢ
A17: Экономичность | B17: 1 | C17: 1 | D17: 4 | E17: 1 | F17: 1 | G17: =GEOMEAN(B17:F17) -> 1.3195079 | H17: =G17/SUM($G$17:$G$21) -> 0.24741207 | I17: =B17*$H$17+C17*$H$18+D17*$H$19+E17*$H$20+F17*$H$21 -> 1.2593474 | J17: =I17/H17 -> 5.0900807
A18: Актуальность | B18: =1/C17 -> 1 | C18: 1 | D18: 2 | E18: 2 | F18: 1 | G18: =GEOMEAN(B18:F18) -> 1.3195079 | H18: =G18/SUM($G$17:$G$21) -> 0.24741207 | I18: =B18*$H$17+C18*$H$18+D18*$H$19+E18*$H$20+F18*$H$21 -> 1.2897912 | J18: =I18/H18 -> 5.2131295
A19: Потенциал развития | B19: =1/D17 -> 0.25 | C19: =1/D18 -> 0.5 | D19: 1 | E19: =1/3 -> 0.33333333 | F19: =1/2 -> 0.5 | G19: =GEOMEAN(B19:F19) -> 0.46105396 | H19: =G19/SUM($G$17:$G$21) -> 0.086449131 | I19: =B19*$H$17+C19*$H$18+D19*$H$19+E19*$H$20+F19*$H$21 -> 0.44748121 | J19: =I19/H19 -> 5.1762372
A20: Простота реализации | B20: =1/E17 -> 1 | C20: =1/E18 -> 0.5 | D20: =1/E19 -> 3 | E20: 1 | F20: 1 | G20: =GEOMEAN(B20:F20) -> 1.0844718 | H20: =G20/SUM($G$17:$G$21) -> 0.20334202 | I20: =B20*$H$17+C20*$H$18+D20*$H$19+E20*$H$20+F20*$H$21 -> 1.0491922 | J20: =I20/H20 -> 5.1597414
A21: Соответствие компетенциям | B21: =1/F17 -> 1 | C21: =1/F18 -> 1 | D21: =1/F19 -> 2 | E21: =1/F20 -> 1 | F21: 1 | G21: =GEOMEAN(B21:F21) -> 1.1486984 | H21: =G21/SUM($G$17:$G$21) -> 0.21538471 | I21: =B21*$H$17+C21*$H$18+D21*$H$19+E21*$H$20+F21*$H$21 -> 1.0864491 | J21: =I21/H21 -> 5.0442258
A22: λmax | B22: =AVERAGE(J17:J21) -> 5.1366829
A23: Индекс согласованности ИС | B23: =(B22-5)/(5-1) -> 0.034170731
A24: Отношение согласованности ОС | B24: =B23/'Концепции и критерии'!$C$38 -> 0.030509581 | C24: =IF(B24<=0.1,"согласована (ОС ≤ 10%)","требует пересмотра") -> согласована (ОС ≤ 10%)
A26: Эксперт: Александр Л.
A27: Критерий | B27: Экономичность | C27: Актуальность | D27: Потенциал развития | E27: Простота реализации | F27: Соответствие компетенциям | G27: Ср. геом. строки | H27: Вес w | I27: (A·w)ᵢ | J27: (A·w)ᵢ / wᵢ
A28: Экономичность | B28: 1 | C28: 2 | D28: 3 | E28: 1 | F28: 1 | G28: =GEOMEAN(B28:F28) -> 1.4309691 | H28: =G28/SUM($G$28:$G$32) -> 0.27176846 | I28: =B28*$H$28+C28*$H$29+D28*$H$30+E28*$H$31+F28*$H$32 -> 1.3750119 | J28: =I28/H28 -> 5.0594978
A29: Актуальность | B29: =1/C28 -> 0.5 | C29: 1 | D29: 1 | E29: 1 | F29: =1/2 -> 0.5 | G29: =GEOMEAN(B29:F29) -> 0.75785828 | H29: =G29/SUM($G$28:$G$32) -> 0.14393181 | I29: =B29*$H$28+C29*$H$29+D29*$H$30+E29*$H$31+F29*$H$32 -> 0.73881585 | J29: =I29/H29 -> 5.1330962
A30: Потенциал развития | B30: =1/D28 -> 0.33333333 | C30: =1/D29 -> 1 | D30: 1 | E30: =1/2 -> 0.5 | F30: =1/2 -> 0.5 | G30: =GEOMEAN(B30:F30) -> 0.60836434 | H30: =G30/SUM($G$28:$G$32) -> 0.11554005 | I30: =B30*$H$28+C30*$H$29+D30*$H$30+E30*$H$31+F30*$H$32 -> 0.58444119 | J30: =I30/H30 -> 5.0583429
A31: Простота реализации | B31: =1/E28 -> 1 | C31: =1/E29 -> 1 | D31: =1/E30 -> 2 | E31: 1 | F31: 1 | G31: =GEOMEAN(B31:F31) -> 1.1486984 | H31: =G31/SUM($G$28:$G$32) -> 0.21815984 | I31: =B31*$H$28+C31*$H$29+D31*$H$30+E31*$H$31+F31*$H$32 -> 1.11554 | J31: =I31/H31 -> 5.1134071
A32: Соответствие компетенциям | B32: =1/F28 -> 1 | C32: =1/F29 -> 2 | D32: =1/F30 -> 2 | E32: =1/F31 -> 1 | F32: 1 | G32: =GEOMEAN(B32:F32) -> 1.3195079 | H32: =G32/SUM($G$28:$G$32) -> 0.25059984 | I32: =B32*$H$28+C32*$H$29+D32*$H$30+E32*$H$31+F32*$H$32 -> 1.2594719 | J32: =I32/H32 -> 5.0258286
A33: λmax | B33: =AVERAGE(J28:J32) -> 5.0780345
A34: Индекс согласованности ИС | B34: =(B33-5)/(5-1) -> 0.019508631
A35: Отношение согласованности ОС | B35: =B34/'Концепции и критерии'!$C$38 -> 0.01741842 | C35: =IF(B35<=0.1,"согласована (ОС ≤ 10%)","требует пересмотра") -> согласована (ОС ≤ 10%)
A37: Коллективная матрица: поэлементное среднее геометрическое оценок трёх экспертов
A38: Критерий | B38: Экономичность | C38: Актуальность | D38: Потенциал развития | E38: Простота реализации | F38: Соответствие компетенциям | G38: Ср. геом. строки | H38: Вес w | I38: (A·w)ᵢ | J38: (A·w)ᵢ / wᵢ
A39: Экономичность | B39: =GEOMEAN(B6,B17,B28) -> 1 | C39: =GEOMEAN(C6,C17,C28) -> 1.5874011 | D39: =GEOMEAN(D6,D17,D28) -> 2.8844991 | E39: =GEOMEAN(E6,E17,E28) -> 1.259921 | F39: =GEOMEAN(F6,F17,F28) -> 1 | G39: =GEOMEAN(B39:F39) -> 1.4197768 | H39: =G39/SUM($G$39:$G$43) -> 0.27198522 | I39: =B39*$H$39+C39*$H$40+D39*$H$41+E39*$H$42+F39*$H$43 -> 1.3692816 | J39: =I39/H39 -> 5.0343972
A40: Актуальность | B40: =GEOMEAN(B7,B18,B29) -> 0.62996052 | C40: =GEOMEAN(C7,C18,C29) -> 1 | D40: =GEOMEAN(D7,D18,D29) -> 1.259921 | E40: =GEOMEAN(E7,E18,E29) -> 1 | F40: =GEOMEAN(F7,F18,F29) -> 1 | G40: =GEOMEAN(B40:F40) -> 0.9548416 | H40: =G40/SUM($G$39:$G$43) -> 0.18291805 | I40: =B40*$H$39+C40*$H$40+D40*$H$41+E40*$H$42+F40*$H$43 -> 0.92772951 | J40: =I40/H40 -> 5.0718314
A41: Потенциал развития | B41: =GEOMEAN(B8,B19,B30) -> 0.34668064 | C41: =GEOMEAN(C8,C19,C30) -> 0.79370053 | D41: =GEOMEAN(D8,D19,D30) -> 1 | E41: =GEOMEAN(E8,E19,E30) -> 0.43679023 | F41: =GEOMEAN(F8,F19,F30) -> 0.5 | G41: =GEOMEAN(B41:F41) -> 0.56985693 | H41: =G41/SUM($G$39:$G$43) -> 0.10916692 | I41: =B41*$H$39+C41*$H$40+D41*$H$41+E41*$H$42+F41*$H$43 -> 0.55296059 | J41: =I41/H41 -> 5.065276
A42: Простота реализации | B42: =GEOMEAN(B9,B20,B31) -> 0.79370053 | C42: =GEOMEAN(C9,C20,C31) -> 1 | D42: =GEOMEAN(D9,D20,D31) -> 2.2894285 | E42: =GEOMEAN(E9,E20,E31) -> 1 | F42: =GEOMEAN(F9,F20,F31) -> 1 | G42: =GEOMEAN(B42:F42) -> 1.1268776 | H42: =G42/SUM($G$39:$G$43) -> 0.21587481 | I42: =B42*$H$39+C42*$H$40+D42*$H$41+E42*$H$42+F42*$H$43 -> 1.0846525 | J42: =I42/H42 -> 5.0244515
A43: Соответствие компетенциям | B43: =GEOMEAN(B10,B21,B32) -> 1 | C43: =GEOMEAN(C10,C21,C32) -> 1 | D43: =GEOMEAN(D10,D21,D32) -> 2 | E43: =GEOMEAN(E10,E21,E32) -> 1 | F43: =GEOMEAN(F10,F21,F32) -> 1 | G43: =GEOMEAN(B43:F43) -> 1.1486984 | H43: =G43/SUM($G$39:$G$43) -> 0.22005499 | I43: =B43*$H$39+C43*$H$40+D43*$H$41+E43*$H$42+F43*$H$43 -> 1.1091669 | J43: =I43/H43 -> 5.0404079
A44: λmax | B44: =AVERAGE(J39:J43) -> 5.0472728
...

Sheet Экономичность
A1: МАИ: парные сравнения — Альтернативы по критерию «Экономичность»
A2: Эксперт заполняет только верхний треугольник (жёлтые ячейки): «во сколько раз строка предпочтительнее столбца». Нижний треугольник — обратные величины.
A4: Эксперт: Александр Ф.
A5: Альтернативы по критерию «Экономичность» | B5: Сплит | C5: Репетиторы | D5: Аудитории | E5: AR-гид | F5: Рецепты | G5: Ср. геом. строки | H5: Вес w | I5: (A·w)ᵢ | J5: (A·w)ᵢ / wᵢ
A6: Сплит | B6: 1 | C6: 3 | D6: 2 | E6: 6 | F6: 2 | G6: =GEOMEAN(B6:F6) -> 2.352158 | H6: =G6/SUM($G$6:$G$10) -> 0.37634228 | I6: =B6*$H$6+C6*$H$7+D6*$H$8+E6*$H$9+F6*$H$10 -> 1.9329644 | J6: =I6/H6 -> 5.1361871
A7: Репетиторы | B7: =1/C6 -> 0.33333333 | C7: 1 | D7: =1/2 -> 0.5 | E7: 2 | F7: =1/3 -> 0.33333333 | G7: =GEOMEAN(B7:F7) -> 0.64439401 | H7: =G7/SUM($G$6:$G$10) -> 0.10310222 | I7: =B7*$H$6+C7*$H$7+D7*$H$8+E7*$H$9+F7*$H$10 -> 0.51861837 | J7: =I7/H7 -> 5.0301378
A8: Аудитории | B8: =1/D6 -> 0.5 | C8: =1/D7 -> 2 | D8: 1 | E8: 4 | F8: =1/2 -> 0.5 | G8: =GEOMEAN(B8:F8) -> 1.1486984 | H8: =G8/SUM($G$6:$G$10) -> 0.18379027 | I8: =B8*$H$6+C8*$H$7+D8*$H$8+E8*$H$9+F8*$H$10 -> 0.92697735 | J8: =I8/H8 -> 5.0436693
A9: AR-гид | B9: =1/E6 -> 0.16666667 | C9: =1/E7 -> 0.5 | D9: =1/E8 -> 0.25 | E9: 1 | F9: =1/6 -> 0.16666667 | G9: =GEOMEAN(B9:F9) -> 0.32219701 | H9: =G9/SUM($G$6:$G$10) -> 0.05155111 | I9: =B9*$H$6+C9*$H$7+D9*$H$8+E9*$H$9+F9*$H$10 -> 0.25930919 | J9: =I9/H9 -> 5.0301378
A10: Рецепты | B10: =1/F6 -> 0.5 | C10: =1/F7 -> 3 | D10: =1/F8 -> 2 | E10: =1/F9 -> 6 | F10: 1 | G10: =GEOMEAN(B10:F10) -> 1.7826025 | H10: =G10/SUM($G$6:$G$10) -> 0.28521412 | I10: =B10*$H$6+C10*$H$7+D10*$H$8+E10*$H$9+F10*$H$10 -> 1.4595791 | J10: =I10/H10 -> 5.1174855
A11: λmax | B11: =AVERAGE(J6:J10) -> 5.0715235
A12: Индекс согласованности ИС | B12: =(B11-5)/(5-1) -> 0.017880879
A13: Отношение согласованности ОС | B13: =B12/'Концепции и критерии'!$C$38 -> 0.015965071 | C13: =IF(B13<=0.1,"согласована (ОС ≤ 10%)","требует пересмотра") -> согласована (ОС ≤ 10%)
A15: Эксперт: Алексей К.
A16: Альтернативы по критерию «Экономичность» | B16: Сплит | C16: Репетиторы | D16: Аудитории | E16: AR-гид | F16: Рецепты | G16: Ср. геом. строки | H16: Вес w | I16: (A·w)ᵢ | J16: (A·w)ᵢ / wᵢ
A17: Сплит | B17: 1 | C17: 3 | D17: 2 | E17: 4 | F17: 2 | G17: =GEOMEAN(B17:F17) -> 2.1689435 | H17: =G17/SUM($G$17:$G$21) -> 0.36908734 | I17: =B17*$H$17+C17*$H$18+D17*$H$19+E17*$H$20+F17*$H$21 -> 1.8851455 | J17: =I17/H17 -> 5.1075864
A18: Репетиторы | B18: =1/C17 -> 0.33333333 | C18: 1 | D18: =1/3 -> 0.33333333 | E18: 1 | F18: =1/3 -> 0.33333333 | G18: =GEOMEAN(B18:F18) -> 0.51728186 | H18: =G18/SUM($G$17:$G$21) -> 0.088025429 | I18: =B18*$H$17+C18*$H$18+D18*$H$19+E18*$H$20+F18*$H$21 -> 0.44741942 | J18: =I18/H18 -> 5.0828429
A19: Аудитории | B19: =1/D17 -> 0.5 | C19: =1/D18 -> 3 | D19: 1 | E19: 3 | F19: 1 | G19: =GEOMEAN(B19:F19) -> 1.35096 | H19: =G19/SUM($G$17:$G$21) -> 0.22989176 | I19: =B19*$H$17+C19*$H$18+D19*$H$19+E19*$H$20+F19*$H$21 -> 1.1577146 | J19: =I19/H19 -> 5.0359117
A20: AR-гид | B20: =1/E17 -> 0.25 | C20: =1/E18 -> 1 | D20: =1/E19 -> 0.33333333 | E20: 1 | F20: =1/3 -> 0.33333333 | G20: =GEOMEAN(B20:F20) -> 0.48835934 | H20: =G20/SUM($G$17:$G$21) -> 0.083103708 | I20: =B20*$H$17+C20*$H$18+D20*$H$19+E20*$H$20+F20*$H$21 -> 0.41666215 | J20: =I20/H20 -> 5.0137612
A21: Рецепты | B21: =1/F17 -> 0.5 | C21: =1/F18 -> 3 | D21: =1/F19 -> 1 | E21: =1/F20 -> 3 | F21: 1 | G21: =GEOMEAN(B21:F21) -> 1.35096 | H21: =G21/SUM($G$17:$G$21) -> 0.22989176 | I21: =B21*$H$17+C21*$H$18+D21*$H$19+E21*$H$20+F21*$H$21 -> 1.1577146 | J21: =I21/H21 -> 5.0359117
A22: λmax | B22: =AVERAGE(J17:J21) -> 5.0552028
A23: Индекс согласованности ИС | B23: =(B22-5)/(5-1) -> 0.013800694
A24: Отношение согласованности ОС | B24: =B23/'Концепции и критерии'!$C$38 -> 0.012322048 | C24: =IF(B24<=0.1,"согласована (ОС ≤ 10%)","требует пересмотра") -> согласована (ОС ≤ 10%)
A26: Эксперт: Александр Л.
A27: Альтернативы по критерию «Экономичность» | B27: Сплит | C27: Репетиторы | D27: Аудитории | E27: AR-гид | F27: Рецепты | G27: Ср. геом. строки | H27: Вес w | I27: (A·w)ᵢ | J27: (A·w)ᵢ / wᵢ
A28: Сплит | B28: 1 | C28: 5 | D28: 2 | E28: 6 | F28: 1 | G28: =GEOMEAN(B28:F28) -> 2.2679332 | H28: =G28/SUM($G$28:$G$32) -> 0.33387065 | I28: =B28*$H$28+C28*$H$29+D28*$H$30+E28*$H$31+F28*$H$32 -> 1.6937212 | J28: =I28/H28 -> 5.0729862
A29: Репетиторы | B29: =1/C28 -> 0.2 | C29: 1 | D29: =1/4 -> 0.25 | E29: 1 | F29: =1/8 -> 0.125 | G29: =GEOMEAN(B29:F29) -> 0.36238983 | H29: =G29/SUM($G$28:$G$32) -> 0.053348718 | I29: =B29*$H$28+C29*$H$29+D29*$H$30+E29*$H$31+F29*$H$32 -> 0.26962082 | J29: =I29/H29 -> 5.0539325
A30: Аудитории | B30: =1/D28 -> 0.5 | C30: =1/D29 -> 4 | D30: 1 | E30: 4 | F30: 1 | G30: =GEOMEAN(B30:F30) -> 1.5157166 | H30: =G30/SUM($G$28:$G$32) -> 0.22313412 | I30: =B30*$H$28+C30*$H$29+D30*$H$30+E30*$H$31+F30*$H$32 -> 1.1474261 | J30: =I30/H30 -> 5.1423159
A31: AR-гид | B31: =1/E28 -> 0.16666667 | C31: =1/E29 -> 1 | D31: =1/E30 -> 0.25 | E31: 1 | F31: =1/8 -> 0.125 | G31: =GEOMEAN(B31:F31) -> 0.34941356 | H31: =G31/SUM($G$28:$G$32) -> 0.051438434 | I31: =B31*$H$28+C31*$H$29+D31*$H$30+E31*$H$31+F31*$H$32 -> 0.2584918 | J31: =I31/H31 -> 5.0252657
A32: Рецепты | B32: =1/F28 -> 1 | C32: =1/F29 -> 8 | D32: =1/F30 -> 1 | E32: =1/F31 -> 8 | F32: 1 | G32: =GEOMEAN(B32:F32) -> 2.2973967 | H32: =G32/SUM($G$28:$G$32) -> 0.33820808 | I32: =B32*$H$28+C32*$H$29+D32*$H$30+E32*$H$31+F32*$H$32 -> 1.7335101 | J32: =I32/H32 -> 5.1255726
A33: λmax | B33: =AVERAGE(J28:J32) -> 5.0840146
A34: Индекс согласованности ИС | B34: =(B33-5)/(5-1) -> 0.021003644
A35: Отношение согласованности ОС | B35: =B34/'Концепции и критерии'!$C$38 -> 0.018753253 | C35: =IF(B35<=0.1,"согласована (ОС ≤ 10%)","требует пересмотра") -> согласована (ОС ≤ 10%)
A37: Коллективная матрица: поэлементное среднее геометрическое оценок трёх экспертов
A38: Альтернативы по критерию «Экономичность» | B38: Сплит | C38: Репетиторы | D38: Аудитории | E38: AR-гид | F38: Рецепты | G38: Ср. геом. строки | H38: Вес w | I38: (A·w)ᵢ | J38: (A·w)ᵢ / wᵢ
A39: Сплит | B39: =GEOMEAN(B6,B17,B28) -> 1 | C39: =GEOMEAN(C6,C17,C28) -> 3.5568933 | D39: =GEOMEAN(D6,D17,D28) -> 2 | E39: =GEOMEAN(E6,E17,E28) -> 5.2414828 | F39: =GEOMEAN(F6,F17,F28) -> 1.5874011 | G39: =GEOMEAN(B39:F39) -> 2.2617694 | H39: =G39/SUM($G$39:$G$43) -> 0.36275846 | I39: =B39*$H$39+C39*$H$40+D39*$H$41+E39*$H$42+F39*$H$43 -> 1.8413246 | J39: =I39/H39 -> 5.0758971
A40: Репетиторы | B40: =GEOMEAN(B7,B18,B29) -> 0.28114422 | C40: =GEOMEAN(C7,C18,C29) -> 1 | D40: =GEOMEAN(D7,D18,D29) -> 0.34668064 | E40: =GEOMEAN(E7,E18,E29) -> 1.259921 | F40: =GEOMEAN(F7,F18,F29) -> 0.24037493 | G40: =GEOMEAN(B40:F40) -> 0.49433146 | H40: =G40/SUM($G$39:$G$43) -> 0.079284349 | I40: =B40*$H$39+C40*$H$40+D40*$H$41+E40*$H$42+F40*$H$43 -> 0.40024465 | J40: =I40/H40 -> 5.0482176
A41: Аудитории | B41: =GEOMEAN(B8,B19,B30) -> 0.5 | C41: =GEOMEAN(C8,C19,C30) -> 2.8844991 | D41: =GEOMEAN(D8,D19,D30) -> 1 | E41: =GEOMEAN(E8,E19,E30) -> 3.6342412 | F41: =GEOMEAN(F8,F19,F30) -> 0.79370053 | G41: =GEOMEAN(B41:F41) -> 1.3299097 | H41: =G41/SUM($G$39:$G$43) -> 0.21330026 | I41: =B41*$H$39+C41*$H$40+D41*$H$41+E41*$H$42+F41*$H$43 -> 1.0701651 | J41: =I41/H41 -> 5.0171768
A42: AR-гид | B42: =GEOMEAN(B9,B20,B31) -> 0.19078571 | C42: =GEOMEAN(C9,C20,C31) -> 0.79370053 | D42: =GEOMEAN(D9,D20,D31) -> 0.2751606 | E42: =GEOMEAN(E9,E20,E31) -> 1 | F42: =GEOMEAN(F9,F20,F31) -> 0.19078571 | G42: =GEOMEAN(B42:F42) -> 0.38024798 | H42: =G42/SUM($G$39:$G$43) -> 0.060986841 | I42: =B42*$H$39+C42*$H$40+D42*$H$41+E42*$H$42+F42*$H$43 -> 0.30593603 | J42: =I42/H42 -> 5.0164269
A43: Рецепты | B43: =GEOMEAN(B10,B21,B32) -> 0.62996052 | C43: =GEOMEAN(C10,C21,C32) -> 4.1601676 | D43: =GEOMEAN(D10,D21,D32) -> 1.259921 | E43: =GEOMEAN(E10,E21,E32) -> 5.2414828 | F43: =GEOMEAN(F10,F21,F32) -> 1 | G43: =GEOMEAN(B43:F43) -> 1.7686599 | H43: =G43/SUM($G$39:$G$43) -> 0.28367009 | I43: =B43*$H$39+C43*$H$40+D43*$H$41+E43*$H$42+F43*$H$43 -> 1.4304327 | J43: =I43/H43 -> 5.0425927
A44: λmax | B44: =AVERAGE(J39:J43) -> 5.0400622
...

Sheet Актуальность
A1: МАИ: парные сравнения — Альтернативы по критерию «Актуальность»
A2: Эксперт заполняет только верхний треугольник (жёлтые ячейки): «во сколько раз строка предпочтительнее столбца». Нижний треугольник — обратные величины.
A4: Эксперт: Александр Ф.
A5: Альтернативы по критерию «Актуальность» | B5: Сплит | C5: Репетиторы | D5: Аудитории | E5: AR-гид | F5: Рецепты | G5: Ср. геом. строки | H5: Вес w | I5: (A·w)ᵢ | J5: (A·w)ᵢ / wᵢ
A6: Сплит | B6: 1 | C6: 1 | D6: 2 | E6: 3 | F6: 3 | G6: =GEOMEAN(B6:F6) -> 1.7826025 | H6: =G6/SUM($G$6:$G$10) -> 0.31793022 | I6: =B6*$H$6+C6*$H$7+D6*$H$8+E6*$H$9+F6*$H$10 -> 1.6186059 | J6: =I6/H6 -> 5.0910728
A7: Репетиторы | B7: =1/C6 -> 1 | C7: 1 | D7: 1 | E7: 2 | F7: 4 | G7: =GEOMEAN(B7:F7) -> 1.5157166 | H7: =G7/SUM($G$6:$G$10) -> 0.27033066 | I7: =B7*$H$6+C7*$H$7+D7*$H$8+E7*$H$9+F7*$H$10 -> 1.3713263 | J7: =I7/H7 -> 5.0727739
A8: Аудитории | B8: =1/D6 -> 0.5 | C8: =1/D7 -> 1 | D8: 1 | E8: 2 | F8: 2 | G8: =GEOMEAN(B8:F8) -> 1.1486984 | H8: =G8/SUM($G$6:$G$10) -> 0.20487233 | I8: =B8*$H$6+C8*$H$7+D8*$H$8+E8*$H$9+F8*$H$10 -> 1.0479017 | J8: =I8/H8 -> 5.1149009
A9: AR-гид | B9: =1/E6 -> 0.33333333 | C9: =1/E7 -> 0.5 | D9: =1/E8 -> 0.5 | E9: 1 | F9: 2 | G9: =GEOMEAN(B9:F9) -> 0.69882712 | H9: =G9/SUM($G$6:$G$10) -> 0.12463702 | I9: =B9*$H$6+C9*$H$7+D9*$H$8+E9*$H$9+F9*$H$10 -> 0.63267479 | J9: =I9/H9 -> 5.0761386
A10: Рецепты | B10: =1/F6 -> 0.33333333 | C10: =1/F7 -> 0.25 | D10: =1/F8 -> 0.5 | E10: =1/F9 -> 0.5 | F10: 1 | G10: =GEOMEAN(B10:F10) -> 0.46105396 | H10: =G10/SUM($G$6:$G$10) -> 0.082229767 | I10: =B10*$H$6+C10*$H$7+D10*$H$8+E10*$H$9+F10*$H$10 -> 0.42054385 | J10: =I10/H10 -> 5.1142532
A11: λmax | B11: =AVERAGE(J6:J10) -> 5.0938279
A12: Индекс согласованности ИС | B12: =(B11-5)/(5-1) -> 0.023456972
A13: Отношение согласованности ОС | B13: =B12/'Концепции и критерии'!$C$38 -> 0.020943725 | C13: =IF(B13<=0.1,"согласована (ОС ≤ 10%)","требует пересмотра") -> согласована (ОС ≤ 10%)
A15: Эксперт: Алексей К.
A16: Альтернативы по критерию «Актуальность» | B16: Сплит | C16: Репетиторы | D16: Аудитории | E16: AR-гид | F16: Рецепты | G16: Ср. геом. строки | H16: Вес w | I16: (A·w)ᵢ | J16: (A·w)ᵢ / wᵢ
A17: Сплит | B17: 1 | C17: =1/2 -> 0.5 | D17: =1/3 -> 0.33333333 | E17: =1/2 -> 0.5 | F17: 2 | G17: =GEOMEAN(B17:F17) -> 0.69882712 | H17: =G17/SUM($G$17:$G$21) -> 0.12500316 | I17: =B17*$H$17+C17*$H$18+D17*$H$19+E17*$H$20+F17*$H$21 -> 0.63706395 | J17: =I17/H17 -> 5.0963826
A18: Репетиторы | B18: =1/C17 -> 2 | C18: 1 | D18: 1 | E18: 2 | F18: 3 | G18: =GEOMEAN(B18:F18) -> 1.6437518 | H18: =G18/SUM($G$17:$G$21) -> 0.2940272 | I18: =B18*$H$17+C18*$H$18+D18*$H$19+E18*$H$20+F18*$H$21 -> 1.5089367 | J18: =I18/H18 -> 5.131963
A19: Аудитории | B19: =1/D17 -> 3 | C19: =1/D18 -> 1 | D19: 1 | E19: 1 | F19: 3 | G19: =GEOMEAN(B19:F19) -> 1.5518456 | H19: =G19/SUM($G$17:$G$21) -> 0.2775874 | I19: =B19*$H$17+C19*$H$18+D19*$H$19+E19*$H$20+F19*$H$21 -> 1.4111089 | J19: =I19/H19 -> 5.083476
A20: AR-гид | B20: =1/E17 -> 2 | C20: =1/E18 -> 0.5 | D20: =1/E19 -> 1 | E20: 1 | F20: 3 | G20: =GEOMEAN(B20:F20) -> 1.2457309 | H20: =G20/SUM($G$17:$G$21) -> 0.22283095 | I20: =B20*$H$17+C20*$H$18+D20*$H$19+E20*$H$20+F20*$H$21 -> 1.1390921 | J20: =I20/H20 -> 5.1119118
A21: Рецепты | B21: =1/F17 -> 0.5 | C21: =1/F18 -> 0.33333333 | D21: =1/F19 -> 0.33333333 | E21: =1/F20 -> 0.33333333 | F21: 1 | G21: =GEOMEAN(B21:F21) -> 0.45032001 | H21: =G21/SUM($G$17:$G$21) -> 0.08055129 | I21: =B21*$H$17+C21*$H$18+D21*$H$19+E21*$H$20+F21*$H$21 -> 0.40786805 | J21: =I21/H21 -> 5.0634577
A22: λmax | B22: =AVERAGE(J17:J21) -> 5.0974382
A23: Индекс согласованности ИС | B23: =(B22-5)/(5-1) -> 0.024359559
A24: Отношение согласованности ОС | B24: =B23/'Концепции и критерии'!$C$38 -> 0.021749606 | C24: =IF(B24<=0.1,"согласована (ОС ≤ 10%)","требует пересмотра") -> согласована (ОС ≤ 10%)
A26: Эксперт: Александр Л.
A27: Альтернативы по критерию «Актуальность» | B27: Сплит | C27: Репетиторы | D27: Аудитории | E27: AR-гид | F27: Рецепты | G27: Ср. геом. строки | H27: Вес w | I27: (A·w)ᵢ | J27: (A·w)ᵢ / wᵢ
A28: Сплит | B28: 1 | C28: 1 | D28: 1 | E28: 2 | F28: 3 | G28: =GEOMEAN(B28:F28) -> 1.4309691 | H28: =G28/SUM($G$28:$G$32) -> 0.26391192 | I28: =B28*$H$28+C28*$H$29+D28*$H$30+E28*$H$31+F28*$H$32 -> 1.3531736 | J28: =I28/H28 -> 5.1273683
A29: Репетиторы | B29: =1/C28 -> 1 | C29: 1 | D29: 1 | E29: 1 | F29: 3 | G29: =GEOMEAN(B29:F29) -> 1.2457309 | H29: =G29/SUM($G$28:$G$32) -> 0.22974867 | I29: =B29*$H$28+C29*$H$29+D29*$H$30+E29*$H$31+F29*$H$32 -> 1.1531658 | J29: =I29/H29 -> 5.0192489
A30: Аудитории | B30: =1/D28 -> 1 | C30: =1/D29 -> 1 | D30: 1 | E30: 1 | F30: 3 | G30: =GEOMEAN(B30:F30) -> 1.2457309 | H30: =G30/SUM($G$28:$G$32) -> 0.22974867 | I30: =B30*$H$28+C30*$H$29+D30*$H$30+E30*$H$31+F30*$H$32 -> 1.1531658 | J30: =I30/H30 -> 5.0192489
A31: AR-гид | B31: =1/E28 -> 0.5 | C31: =1/E29 -> 1 | D31: =1/E30 -> 1 | E31: 1 | F31: 3 | G31: =GEOMEAN(B31:F31) -> 1.0844718 | H31: =G31/SUM($G$28:$G$32) -> 0.20000784 | I31: =B31*$H$28+C31*$H$29+D31*$H$30+E31*$H$31+F31*$H$32 -> 1.0212098 | J31: =I31/H31 -> 5.105849
A32: Рецепты | B32: =1/F28 -> 0.33333333 | C32: =1/F29 -> 0.33333333 | D32: =1/F30 -> 0.33333333 | E32: =1/F31 -> 0.33333333 | F32: 1 | G32: =GEOMEAN(B32:F32) -> 0.41524365 | H32: =G32/SUM($G$28:$G$32) -> 0.076582891 | I32: =B32*$H$28+C32*$H$29+D32*$H$30+E32*$H$31+F32*$H$32 -> 0.38438859 | J32: =I32/H32 -> 5.0192489
A33: λmax | B33: =AVERAGE(J28:J32) -> 5.0581928
A34: Индекс согласованности ИС | B34: =(B33-5)/(5-1) -> 0.014548202
A35: Отношение согласованности ОС | B35: =B34/'Концепции и критерии'!$C$38 -> 0.012989466 | C35: =IF(B35<=0.1,"согласована (ОС ≤ 10%)","требует пересмотра") -> согласована (ОС ≤ 10%)
A37: Коллективная матрица: поэлементное среднее геометрическое оценок трёх экспертов
A38: Альтернативы по критерию «Актуальность» | B38: Сплит | C38: Репетиторы | D38: Аудитории | E38: AR-гид | F38: Рецепты | G38: Ср. геом. строки | H38: Вес w | I38: (A·w)ᵢ | J38: (A·w)ᵢ / wᵢ
A39: Сплит | B39: =GEOMEAN(B6,B17,B28) -> 1 | C39: =GEOMEAN(C6,C17,C28) -> 0.79370053 | D39: =GEOMEAN(D6,D17,D28) -> 0.87358046 | E39: =GEOMEAN(E6,E17,E28) -> 1.4422496 | F39: =GEOMEAN(F6,F17,F28) -> 2.6207414 | G39: =GEOMEAN(B39:F39) -> 1.2125086 | H39: =G39/SUM($G$39:$G$43) -> 0.22459673 | I39: =B39*$H$39+C39*$H$40+D39*$H$41+E39*$H$42+F39*$H$43 -> 1.1266956 | J39: =I39/H39 -> 5.0165271
A40: Репетиторы | B40: =GEOMEAN(B7,B18,B29) -> 1.259921 | C40: =GEOMEAN(C7,C18,C29) -> 1 | D40: =GEOMEAN(D7,D18,D29) -> 1 | E40: =GEOMEAN(E7,E18,E29) -> 1.5874011 | F40: =GEOMEAN(F7,F18,F29) -> 3.3019272 | G40: =GEOMEAN(B40:F40) -> 1.4586782 | H40: =G40/SUM($G$39:$G$43) -> 0.27019549 | I40: =B40*$H$39+C40*$H$40+D40*$H$41+E40*$H$42+F40*$H$43 -> 1.3534825 | J40: =I40/H40 -> 5.0092713
A41: Аудитории | B41: =GEOMEAN(B8,B19,B30) -> 1.1447142 | C41: =GEOMEAN(C8,C19,C30) -> 1 | D41: =GEOMEAN(D8,D19,D30) -> 1 | E41: =GEOMEAN(E8,E19,E30) -> 1.259921 | F41: =GEOMEAN(F8,F19,F30) -> 2.6207414 | G41: =GEOMEAN(B41:F41) -> 1.3046467 | H41: =G41/SUM($G$39:$G$43) -> 0.24166375 | I41: =B41*$H$39+C41*$H$40+D41*$H$41+E41*$H$42+F41*$H$43 -> 1.2123584 | J41: =I41/H41 -> 5.016716
A42: AR-гид | B42: =GEOMEAN(B9,B20,B31) -> 0.69336127 | C42: =GEOMEAN(C9,C20,C31) -> 0.62996052 | D42: =GEOMEAN(D9,D20,D31) -> 0.79370053 | E42: =GEOMEAN(E9,E20,E31) -> 1 | F42: =GEOMEAN(F9,F20,F31) -> 2.6207414 | G42: =GEOMEAN(B42:F42) -> 0.98100394 | H42: =G42/SUM($G$39:$G$43) -> 0.1817144 | I42: =B42*$H$39+C42*$H$40+D42*$H$41+E42*$H$42+F42*$H$43 -> 0.91391651 | J42: =I42/H42 -> 5.0294116
A43: Рецепты | B43: =GEOMEAN(B10,B21,B32) -> 0.38157141 | C43: =GEOMEAN(C10,C21,C32) -> 0.30285343 | D43: =GEOMEAN(D10,D21,D32) -> 0.38157141 | E43: =GEOMEAN(E10,E21,E32) -> 0.38157141 | F43: =GEOMEAN(F10,F21,F32) -> 1 | G43: =GEOMEAN(B43:F43) -> 0.44176571 | H43: =G43/SUM($G$39:$G$43) -> 0.081829631 | I43: =B43*$H$39+C43*$H$40+D43*$H$41+E43*$H$42+F43*$H$43 -> 0.41090795 | J43: =I43/H43 -> 5.0215056
A44: λmax | B44: =AVERAGE(J39:J43) -> 5.0186863
...

Sheet Потенциал развития
A1: МАИ: парные сравнения — Альтернативы по критерию «Потенциал развития»
A2: Эксперт заполняет только верхний треугольник (жёлтые ячейки): «во сколько раз строка предпочтительнее столбца». Нижний треугольник — обратные величины.
A4: Эксперт: Александр Ф.
A5: Альтернативы по критерию «Потенциал развития» | B5: Сплит | C5: Репетиторы | D5: Аудитории | E5: AR-гид | F5: Рецепты | G5: Ср. геом. строки | H5: Вес w | I5: (A·w)ᵢ | J5: (A·w)ᵢ / wᵢ
A6: Сплит | B6: 1 | C6: =1/2 -> 0.5 | D6: 1 | E6: =1/2 -> 0.5 | F6: 1 | G6: =GEOMEAN(B6:F6) -> 0.75785828 | H6: =G6/SUM($G$6:$G$10) -> 0.13626027 | I6: =B6*$H$6+C6*$H$7+D6*$H$8+E6*$H$9+F6*$H$10 -> 0.68856404 | J6: =I6/H6 -> 5.0533001
A7: Репетиторы | B7: =1/C6 -> 2 | C7: 1 | D7: 5 | E7: 1 | F7: 2 | G7: =GEOMEAN(B7:F7) -> 1.8205642 | H7: =G7/SUM($G$6:$G$10) -> 0.32733108 | I7: =B7*$H$6+C7*$H$7+D7*$H$8+E7*$H$9+F7*$H$10 -> 1.6909507 | J7: =I7/H7 -> 5.1658727
A8: Аудитории | B8: =1/D6 -> 1 | C8: =1/D7 -> 0.2 | D8: 1 | E8: =1/3 -> 0.33333333 | F8: 1 | G8: =GEOMEAN(B8:F8) -> 0.58181076 | H8: =G8/SUM($G$6:$G$10) -> 0.10460754 | I8: =B8*$H$6+C8*$H$7+D8*$H$8+E8*$H$9+F8*$H$10 -> 0.54110791 | J8: =I8/H8 -> 5.1727428
A9: AR-гид | B9: =1/E6 -> 2 | C9: =1/E7 -> 1 | D9: =1/E8 -> 3 | E9: 1 | F9: 2 | G9: =GEOMEAN(B9:F9) -> 1.6437518 | H9: =G9/SUM($G$6:$G$10) -> 0.29554083 | I9: =B9*$H$6+C9*$H$7+D9*$H$8+E9*$H$9+F9*$H$10 -> 1.4817356 | J9: =I9/H9 -> 5.0136409
A10: Рецепты | B10: =1/F6 -> 1 | C10: =1/F7 -> 0.5 | D10: =1/F8 -> 1 | E10: =1/F9 -> 0.5 | F10: 1 | G10: =GEOMEAN(B10:F10) -> 0.75785828 | H10: =G10/SUM($G$6:$G$10) -> 0.13626027 | I10: =B10*$H$6+C10*$H$7+D10*$H$8+E10*$H$9+F10*$H$10 -> 0.68856404 | J10: =I10/H10 -> 5.0533001
A11: λmax | B11: =AVERAGE(J6:J10) -> 5.0917713
A12: Индекс согласованности ИС | B12: =(B11-5)/(5-1) -> 0.022942835
A13: Отношение согласованности ОС | B13: =B12/'Концепции и критерии'!$C$38 -> 0.020484674 | C13: =IF(B13<=0.1,"согласована (ОС ≤ 10%)","требует пересмотра") -> согласована (ОС ≤ 10%)
A15: Эксперт: Алексей К.
A16: Альтернативы по критерию «Потенциал развития» | B16: Сплит | C16: Репетиторы | D16: Аудитории | E16: AR-гид | F16: Рецепты | G16: Ср. геом. строки | H16: Вес w | I16: (A·w)ᵢ | J16: (A·w)ᵢ / wᵢ
A17: Сплит | B17: 1 | C17: =1/2 -> 0.5 | D17: 2 | E17: =1/2 -> 0.5 | F17: 2 | G17: =GEOMEAN(B17:F17) -> 1 | H17: =G17/SUM($G$17:$G$21) -> 0.1640383 | I17: =B17*$H$17+C17*$H$18+D17*$H$19+E17*$H$20+F17*$H$21 -> 0.82270671 | J17: =I17/H17 -> 5.015333
A18: Репетиторы | B18: =1/C17 -> 2 | C18: 1 | D18: 4 | E18: 2 | F18: 4 | G18: =GEOMEAN(B18:F18) -> 2.2973967 | H18: =G18/SUM($G$17:$G$21) -> 0.37686106 | I18: =B18*$H$17+C18*$H$18+D18*$H$19+E18*$H$20+F18*$H$21 -> 1.9440557 | J18: =I18/H18 -> 5.1585475
A19: Аудитории | B19: =1/D17 -> 0.5 | C19: =1/D18 -> 0.25 | D19: 1 | E19: =1/4 -> 0.25 | F19: 1 | G19: =GEOMEAN(B19:F19) -> 0.5 | H19: =G19/SUM($G$17:$G$21) -> 0.082019152 | I19: =B19*$H$17+C19*$H$18+D19*$H$19+E19*$H$20+F19*$H$21 -> 0.41135336 | J19: =I19/H19 -> 5.015333
A20: AR-гид | B20: =1/E17 -> 2 | C20: =1/E18 -> 0.5 | D20: =1/E19 -> 4 | E20: 1 | F20: 5 | G20: =GEOMEAN(B20:F20) -> 1.8205642 | H20: =G20/SUM($G$17:$G$21) -> 0.29864226 | I20: =B20*$H$17+C20*$H$18+D20*$H$19+E20*$H$20+F20*$H$21 -> 1.5354221 | J20: =I20/H20 -> 5.1413423
A21: Рецепты | B21: =1/F17 -> 0.5 | C21: =1/F18 -> 0.25 | D21: =1/F19 -> 1 | E21: =1/F20 -> 0.2 | F21: 1 | G21: =GEOMEAN(B21:F21) -> 0.47817625 | H21: =G21/SUM($G$17:$G$21) -> 0.078439221 | I21: =B21*$H$17+C21*$H$18+D21*$H$19+E21*$H$20+F21*$H$21 -> 0.39642124 | J21: =I21/H21 -> 5.0538651
A22: λmax | B22: =AVERAGE(J17:J21) -> 5.0768842
A23: Индекс согласованности ИС | B23: =(B22-5)/(5-1) -> 0.019221044
A24: Отношение согласованности ОС | B24: =B23/'Концепции и критерии'!$C$38 -> 0.017161647 | C24: =IF(B24<=0.1,"согласована (ОС ≤ 10%)","требует пересмотра") -> согласована (ОС ≤ 10%)
A26: Эксперт: Александр Л.
A27: Альтернативы по критерию «Потенциал развития» | B27: Сплит | C27: Репетиторы | D27: Аудитории | E27: AR-гид | F27: Рецепты | G27: Ср. геом. строки | H27: Вес w | I27: (A·w)ᵢ | J27: (A·w)ᵢ / wᵢ
A28: Сплит | B28: 1 | C28: 2 | D28: 3 | E28: 1 | F28: 2 | G28: =GEOMEAN(B28:F28) -> 1.6437518 | H28: =G28/SUM($G$28:$G$32) -> 0.30273221 | I28: =B28*$H$28+C28*$H$29+D28*$H$30+E28*$H$31+F28*$H$32 -> 1.5575681 | J28: =I28/H28 -> 5.1450359
A29: Репетиторы | B29: =1/C28 -> 0.5 | C29: 1 | D29: 3 | E29: 1 | F29: 2 | G29: =GEOMEAN(B29:F29) -> 1.2457309 | H29: =G29/SUM($G$28:$G$32) -> 0.22942812 | I29: =B29*$H$28+C29*$H$29+D29*$H$30+E29*$H$31+F29*$H$32 -> 1.1767739 | J29: =I29/H29 -> 5.1291617
A30: Аудитории | B30: =1/D28 -> 0.33333333 | C30: =1/D29 -> 0.33333333 | D30: 1 | E30: =1/2 -> 0.5 | F30: 1 | G30: =GEOMEAN(B30:F30) -> 0.56097757 | H30: =G30/SUM($G$28:$G$32) -> 0.10331607 | I30: =B30*$H$28+C30*$H$29+D30*$H$30+E30*$H$31+F30*$H$32 -> 0.52371858 | J30: =I30/H30 -> 5.0690911
A31: AR-гид | B31: =1/E28 -> 1 | C31: =1/E29 -> 1 | D31: =1/E30 -> 2 | E31: 1 | F31: 2 | G31: =GEOMEAN(B31:F31) -> 1.3195079 | H31: =G31/SUM($G$28:$G$32) -> 0.24301573 | I31: =B31*$H$28+C31*$H$29+D31*$H$30+E31*$H$31+F31*$H$32 -> 1.2248239 | J31: =I31/H31 -> 5.0401015
A32: Рецепты | B32: =1/F28 -> 0.5 | C32: =1/F29 -> 0.5 | D32: =1/F30 -> 1 | E32: =1/F31 -> 0.5 | F32: 1 | G32: =GEOMEAN(B32:F32) -> 0.65975396 | H32: =G32/SUM($G$28:$G$32) -> 0.12150787 | I32: =B32*$H$28+C32*$H$29+D32*$H$30+E32*$H$31+F32*$H$32 -> 0.61241197 | J32: =I32/H32 -> 5.0401015
A33: λmax | B33: =AVERAGE(J28:J32) -> 5.0846983
A34: Индекс согласованности ИС | B34: =(B33-5)/(5-1) -> 0.02117458
A35: Отношение согласованности ОС | B35: =B34/'Концепции и критерии'!$C$38 -> 0.018905875 | C35: =IF(B35<=0.1,"согласована (ОС ≤ 10%)","требует пересмотра") -> согласована (ОС ≤ 10%)
A37: Коллективная матрица: поэлементное среднее геометрическое оценок трёх экспертов
A38: Альтернативы по критерию «Потенциал развития» | B38: Сплит | C38: Репетиторы | D38: Аудитории | E38: AR-гид | F38: Рецепты | G38: Ср. геом. строки | H38: Вес w | I38: (A·w)ᵢ | J38: (A·w)ᵢ / wᵢ
A39: Сплит | B39: =GEOMEAN(B6,B17,B28) -> 1 | C39: =GEOMEAN(C6,C17,C28) -> 0.79370053 | D39: =GEOMEAN(D6,D17,D28) -> 1.8171206 | E39: =GEOMEAN(E6,E17,E28) -> 0.62996052 | F39: =GEOMEAN(F6,F17,F28) -> 1.5874011 | G39: =GEOMEAN(B39:F39) -> 1.0759896 | H39: =G39/SUM($G$39:$G$43) -> 0.19361632 | I39: =B39*$H$39+C39*$H$40+D39*$H$41+E39*$H$42+F39*$H$43 -> 0.97635221 | J39: =I39/H39 -> 5.0427165
A40: Репетиторы | B40: =GEOMEAN(B7,B18,B29) -> 1.259921 | C40: =GEOMEAN(C7,C18,C29) -> 1 | D40: =GEOMEAN(D7,D18,D29) -> 3.9148676 | E40: =GEOMEAN(E7,E18,E29) -> 1.259921 | F40: =GEOMEAN(F7,F18,F29) -> 2.5198421 | G40: =GEOMEAN(B40:F40) -> 1.733626 | H40: =G40/SUM($G$39:$G$43) -> 0.31195309 | I40: =B40*$H$39+C40*$H$40+D40*$H$41+E40*$H$42+F40*$H$43 -> 1.5806185 | J40: =I40/H40 -> 5.0668469
A41: Аудитории | B41: =GEOMEAN(B8,B19,B30) -> 0.55032121 | C41: =GEOMEAN(C8,C19,C30) -> 0.25543648 | D41: =GEOMEAN(D8,D19,D30) -> 1 | E41: =GEOMEAN(E8,E19,E30) -> 0.34668064 | F41: =GEOMEAN(F8,F19,F30) -> 1 | G41: =GEOMEAN(B41:F41) -> 0.54646928 | H41: =G41/SUM($G$39:$G$43) -> 0.098333077 | I41: =B41*$H$39+C41*$H$40+D41*$H$41+E41*$H$42+F41*$H$43 -> 0.49485236 | J41: =I41/H41 -> 5.03241
A42: AR-гид | B42: =GEOMEAN(B9,B20,B31) -> 1.5874011 | C42: =GEOMEAN(C9,C20,C31) -> 0.79370053 | D42: =GEOMEAN(D9,D20,D31) -> 2.8844991 | E42: =GEOMEAN(E9,E20,E31) -> 1 | F42: =GEOMEAN(F9,F20,F31) -> 2.7144176 | G42: =GEOMEAN(B42:F42) -> 1.5805858 | H42: =G42/SUM($G$39:$G$43) -> 0.28441465 | I42: =B42*$H$39+C42*$H$40+D42*$H$41+E42*$H$42+F42*$H$43 -> 1.4261543 | J42: =I42/H42 -> 5.0143491
A43: Рецепты | B43: =GEOMEAN(B10,B21,B32) -> 0.62996052 | C43: =GEOMEAN(C10,C21,C32) -> 0.39685026 | D43: =GEOMEAN(D10,D21,D32) -> 1 | E43: =GEOMEAN(E10,E21,E32) -> 0.36840315 | F43: =GEOMEAN(F10,F21,F32) -> 1 | G43: =GEOMEAN(B43:F43) -> 0.62065844 | H43: =G43/SUM($G$39:$G$43) -> 0.11168286 | I43: =B43*$H$39+C43*$H$40+D43*$H$41+E43*$H$42+F43*$H$43 -> 0.5605645 | J43: =I43/H43 -> 5.0192525
A44: λmax | B44: =AVERAGE(J39:J43) -> 5.035115
...

Sheet Простота реализации
A1: МАИ: парные сравнения — Альтернативы по критерию «Простота реализации»
A2: Эксперт заполняет только верхний треугольник (жёлтые ячейки): «во сколько раз строка предпочтительнее столбца». Нижний треугольник — обратные величины.
A4: Эксперт: Александр Ф.
A5: Альтернативы по критерию «Простота реализации» | B5: Сплит | C5: Репетиторы | D5: Аудитории | E5: AR-гид | F5: Рецепты | G5: Ср. геом. строки | H5: Вес w | I5: (A·w)ᵢ | J5: (A·w)ᵢ / wᵢ
A6: Сплит | B6: 1 | C6: 4 | D6: 2 | E6: 9 | F6: 1 | G6: =GEOMEAN(B6:F6) -> 2.352158 | H6: =G6/SUM($G$6:$G$10) -> 0.36166796 | I6: =B6*$H$6+C6*$H$7+D6*$H$8+E6*$H$9+F6*$H$10 -> 1.8157689 | J6: =I6/H6 -> 5.0205412
A7: Репетиторы | B7: =1/C6 -> 0.25 | C7: 1 | D7: =1/3 -> 0.33333333 | E7: 2 | F7: =1/3 -> 0.33333333 | G7: =GEOMEAN(B7:F7) -> 0.56097757 | H7: =G7/SUM($G$6:$G$10) -> 0.086255946 | I7: =B7*$H$6+C7*$H$7+D7*$H$8+E7*$H$9+F7*$H$10 -> 0.43683526 | J7: =I7/H7 -> 5.0644075
A8: Аудитории | B8: =1/D6 -> 0.5 | C8: =1/D7 -> 3 | D8: 1 | E8: 4 | F8: =1/2 -> 0.5 | G8: =GEOMEAN(B8:F8) -> 1.2457309 | H8: =G8/SUM($G$6:$G$10) -> 0.19154366 | I8: =B8*$H$6+C8*$H$7+D8*$H$8+E8*$H$9+F8*$H$10 -> 0.97129932 | J8: =I8/H8 -> 5.0709029
A9: AR-гид | B9: =1/E6 -> 0.11111111 | C9: =1/E7 -> 0.5 | D9: =1/E8 -> 0.25 | E9: 1 | F9: =1/6 -> 0.16666667 | G9: =GEOMEAN(B9:F9) -> 0.29710041 | H9: =G9/SUM($G$6:$G$10) -> 0.045682177 | I9: =B9*$H$6+C9*$H$7+D9*$H$8+E9*$H$9+F9*$H$10 -> 0.22935644 | J9: =I9/H9 -> 5.0206985
A10: Рецепты | B10: =1/F6 -> 1 | C10: =1/F7 -> 3 | D10: =1/F8 -> 2 | E10: =1/F9 -> 6 | F10: 1 | G10: =GEOMEAN(B10:F10) -> 2.0476725 | H10: =G10/SUM($G$6:$G$10) -> 0.31485025 | I10: =B10*$H$6+C10*$H$7+D10*$H$8+E10*$H$9+F10*$H$10 -> 1.5924664 | J10: =I10/H10 -> 5.0578535
A11: λmax | B11: =AVERAGE(J6:J10) -> 5.0468807
A12: Индекс согласованности ИС | B12: =(B11-5)/(5-1) -> 0.011720181
A13: Отношение согласованности ОС | B13: =B12/'Концепции и критерии'!$C$38 -> 0.010464447 | C13: =IF(B13<=0.1,"согласована (ОС ≤ 10%)","требует пересмотра") -> согласована (ОС ≤ 10%)
A15: Эксперт: Алексей К.
A16: Альтернативы по критерию «Простота реализации» | B16: Сплит | C16: Репетиторы | D16: Аудитории | E16: AR-гид | F16: Рецепты | G16: Ср. геом. строки | H16: Вес w | I16: (A·w)ᵢ | J16: (A·w)ᵢ / wᵢ
A17: Сплит | B17: 1 | C17: 3 | D17: 2 | E17: 7 | F17: 1 | G17: =GEOMEAN(B17:F17) -> 2.1117858 | H17: =G17/SUM($G$17:$G$21) -> 0.33160601 | I17: =B17*$H$17+C17*$H$18+D17*$H$19+E17*$H$20+F17*$H$21 -> 1.701098 | J17: =I17/H17 -> 5.1298767
A18: Репетиторы | B18: =1/C17 -> 0.33333333 | C18: 1 | D18: =1/3 -> 0.33333333 | E18: 2 | F18: =1/3 -> 0.33333333 | G18: =GEOMEAN(B18:F18) -> 0.59420082 | H18: =G18/SUM($G$17:$G$21) -> 0.093305187 | I18: =B18*$H$17+C18*$H$18+D18*$H$19+E18*$H$20+F18*$H$21 -> 0.46864158 | J18: =I18/H18 -> 5.0226745
A19: Аудитории | B19: =1/D17 -> 0.5 | C19: =1/D18 -> 3 | D19: 1 | E19: 7 | F19: 1 | G19: =GEOMEAN(B19:F19) -> 1.6004343 | H19: =G19/SUM($G$17:$G$21) -> 0.25131036 | I19: =B19*$H$17+C19*$H$18+D19*$H$19+E19*$H$20+F19*$H$21 -> 1.2839846 | J19: =I19/H19 -> 5.109159
A20: AR-гид | B20: =1/E17 -> 0.14285714 | C20: =1/E18 -> 0.5 | D20: =1/E19 -> 0.14285714 | E20: 1 | F20: =1/6 -> 0.16666667 | G20: =GEOMEAN(B20:F20) -> 0.27933447 | H20: =G20/SUM($G$17:$G$21) -> 0.043862873 | I20: =B20*$H$17+C20*$H$18+D20*$H$19+E20*$H$20+F20*$H$21 -> 0.22044183 | J20: =I20/H20 -> 5.0257043
A21: Рецепты | B21: =1/F17 -> 1 | C21: =1/F18 -> 3 | D21: =1/F19 -> 1 | E21: =1/F20 -> 6 | F21: 1 | G21: =GEOMEAN(B21:F21) -> 1.7826025 | H21: =G21/SUM($G$17:$G$21) -> 0.27991556 | I21: =B21*$H$17+C21*$H$18+D21*$H$19+E21*$H$20+F21*$H$21 -> 1.4059247 | J21: =I21/H21 -> 5.0226745
A22: λmax | B22: =AVERAGE(J17:J21) -> 5.0620178
A23: Индекс согласованности ИС | B23: =(B22-5)/(5-1) -> 0.015504445
A24: Отношение согласованности ОС | B24: =B23/'Концепции и критерии'!$C$38 -> 0.013843254 | C24: =IF(B24<=0.1,"согласована (ОС ≤ 10%)","требует пересмотра") -> согласована (ОС ≤ 10%)
A26: Эксперт: Александр Л.
A27: Альтернативы по критерию «Простота реализации» | B27: Сплит | C27: Репетиторы | D27: Аудитории | E27: AR-гид | F27: Рецепты | G27: Ср. геом. строки | H27: Вес w | I27: (A·w)ᵢ | J27: (A·w)ᵢ / wᵢ
A28: Сплит | B28: 1 | C28: 3 | D28: 2 | E28: 3 | F28: 1 | G28: =GEOMEAN(B28:F28) -> 1.7826025 | H28: =G28/SUM($G$28:$G$32) -> 0.31463379 | I28: =B28*$H$28+C28*$H$29+D28*$H$30+E28*$H$31+F28*$H$32 -> 1.5877317 | J28: =I28/H28 -> 5.0462847
A29: Репетиторы | B29: =1/C28 -> 0.33333333 | C29: 1 | D29: =1/2 -> 0.5 | E29: 1 | F29: =1/3 -> 0.33333333 | G29: =GEOMEAN(B29:F29) -> 0.56097757 | H29: =G29/SUM($G$28:$G$32) -> 0.099013944 | I29: =B29*$H$28+C29*$H$29+D29*$H$30+E29*$H$31+F29*$H$32 -> 0.49545254 | J29: =I29/H29 -> 5.0038663
A30: Аудитории | B30: =1/D28 -> 0.5 | C30: =1/D29 -> 2 | D30: 1 | E30: 2 | F30: 1 | G30: =GEOMEAN(B30:F30) -> 1.1486984 | H30: =G30/SUM($G$28:$G$32) -> 0.20274813 | I30: =B30*$H$28+C30*$H$29+D30*$H$30+E30*$H$31+F30*$H$32 -> 1.0351749 | J30: =I30/H30 -> 5.1057185
A31: AR-гид | B31: =1/E28 -> 0.33333333 | C31: =1/E29 -> 1 | D31: =1/E30 -> 0.5 | E31: 1 | F31: =1/4 -> 0.25 | G31: =GEOMEAN(B31:F31) -> 0.52961192 | H31: =G31/SUM($G$28:$G$32) -> 0.093477828 | I31: =B31*$H$28+C31*$H$29+D31*$H$30+E31*$H$31+F31*$H$32 -> 0.47127534 | J31: =I31/H31 -> 5.0415735
A32: Рецепты | B32: =1/F28 -> 1 | C32: =1/F29 -> 3 | D32: =1/F30 -> 1 | E32: =1/F31 -> 4 | F32: 1 | G32: =GEOMEAN(B32:F32) -> 1.6437518 | H32: =G32/SUM($G$28:$G$32) -> 0.29012631 | I32: =B32*$H$28+C32*$H$29+D32*$H$30+E32*$H$31+F32*$H$32 -> 1.4784614 | J32: =I32/H32 -> 5.0959232
A33: λmax | B33: =AVERAGE(J28:J32) -> 5.0586732
A34: Индекс согласованности ИС | B34: =(B33-5)/(5-1) -> 0.014668308
A35: Отношение согласованности ОС | B35: =B34/'Концепции и критерии'!$C$38 -> 0.013096703 | C35: =IF(B35<=0.1,"согласована (ОС ≤ 10%)","требует пересмотра") -> согласована (ОС ≤ 10%)
A37: Коллективная матрица: поэлементное среднее геометрическое оценок трёх экспертов
A38: Альтернативы по критерию «Простота реализации» | B38: Сплит | C38: Репетиторы | D38: Аудитории | E38: AR-гид | F38: Рецепты | G38: Ср. геом. строки | H38: Вес w | I38: (A·w)ᵢ | J38: (A·w)ᵢ / wᵢ
A39: Сплит | B39: =GEOMEAN(B6,B17,B28) -> 1 | C39: =GEOMEAN(C6,C17,C28) -> 3.3019272 | D39: =GEOMEAN(D6,D17,D28) -> 2 | E39: =GEOMEAN(E6,E17,E28) -> 5.7387935 | F39: =GEOMEAN(F6,F17,F28) -> 1 | G39: =GEOMEAN(B39:F39) -> 2.0688244 | H39: =G39/SUM($G$39:$G$43) -> 0.33755689 | I39: =B39*$H$39+C39*$H$40+D39*$H$41+E39*$H$42+F39*$H$43 -> 1.702716 | J39: =I39/H39 -> 5.0442341
A40: Репетиторы | B40: =GEOMEAN(B7,B18,B29) -> 0.30285343 | C40: =GEOMEAN(C7,C18,C29) -> 1 | D40: =GEOMEAN(D7,D18,D29) -> 0.38157141 | E40: =GEOMEAN(E7,E18,E29) -> 1.5874011 | F40: =GEOMEAN(F7,F18,F29) -> 0.33333333 | G40: =GEOMEAN(B40:F40) -> 0.57184029 | H40: =G40/SUM($G$39:$G$43) -> 0.093303537 | I40: =B40*$H$39+C40*$H$40+D40*$H$41+E40*$H$42+F40*$H$43 -> 0.46783302 | J40: =I40/H40 -> 5.0140973
A41: Аудитории | B41: =GEOMEAN(B8,B19,B30) -> 0.5 | C41: =GEOMEAN(C8,C19,C30) -> 2.6207414 | D41: =GEOMEAN(D8,D19,D30) -> 1 | E41: =GEOMEAN(E8,E19,E30) -> 3.8258624 | F41: =GEOMEAN(F8,F19,F30) -> 0.79370053 | G41: =GEOMEAN(B41:F41) -> 1.3181233 | H41: =G41/SUM($G$39:$G$43) -> 0.21506978 | I41: =B41*$H$39+C41*$H$40+D41*$H$41+E41*$H$42+F41*$H$43 -> 1.0839954 | J41: =I41/H41 -> 5.040203
A42: AR-гид | B42: =GEOMEAN(B9,B20,B31) -> 0.17425265 | C42: =GEOMEAN(C9,C20,C31) -> 0.62996052 | D42: =GEOMEAN(D9,D20,D31) -> 0.26137898 | E42: =GEOMEAN(E9,E20,E31) -> 1 | F42: =GEOMEAN(F9,F20,F31) -> 0.19078571 | G42: =GEOMEAN(B42:F42) -> 0.35290828 | H42: =G42/SUM($G$39:$G$43) -> 0.057581796 | I42: =B42*$H$39+C42*$H$40+D42*$H$41+E42*$H$42+F42*$H$43 -> 0.28795992 | J42: =I42/H42 -> 5.0008846
A43: Рецепты | B43: =GEOMEAN(B10,B21,B32) -> 1 | C43: =GEOMEAN(C10,C21,C32) -> 3 | D43: =GEOMEAN(D10,D21,D32) -> 1.259921 | E43: =GEOMEAN(E10,E21,E32) -> 5.2414828 | F43: =GEOMEAN(F10,F21,F32) -> 1 | G43: =GEOMEAN(B43:F43) -> 1.8171206 | H43: =G43/SUM($G$39:$G$43) -> 0.29648799 | I43: =B43*$H$39+C43*$H$40+D43*$H$41+E43*$H$42+F43*$H$43 -> 1.4867404 | J43: =I43/H43 -> 5.0145047
A44: λmax | B44: =AVERAGE(J39:J43) -> 5.0227848
...

Sheet Соответствие компетенциям
A1: МАИ: парные сравнения — Альтернативы по критерию «Соответствие компетенциям»
A2: Эксперт заполняет только верхний треугольник (жёлтые ячейки): «во сколько раз строка предпочтительнее столбца». Нижний треугольник — обратные величины.
A4: Эксперт: Александр Ф.
A5: Альтернативы по критерию «Соответствие компетенциям» | B5: Сплит | C5: Репетиторы | D5: Аудитории | E5: AR-гид | F5: Рецепты | G5: Ср. геом. строки | H5: Вес w | I5: (A·w)ᵢ | J5: (A·w)ᵢ / wᵢ
A6: Сплит | B6: 1 | C6: 2 | D6: 1 | E6: 4 | F6: 1 | G6: =GEOMEAN(B6:F6) -> 1.5157166 | H6: =G6/SUM($G$6:$G$10) -> 0.27603286 | I6: =B6*$H$6+C6*$H$7+D6*$H$8+E6*$H$9+F6*$H$10 -> 1.4340066 | J6: =I6/H6 -> 5.1950575
A7: Репетиторы | B7: =1/C6 -> 0.5 | C7: 1 | D7: =1/2 -> 0.5 | E7: 2 | F7: 2 | G7: =GEOMEAN(B7:F7) -> 1 | H7: =G7/SUM($G$6:$G$10) -> 0.18211377 | I7: =B7*$H$6+C7*$H$7+D7*$H$8+E7*$H$9+F7*$H$10 -> 0.95481217 | J7: =I7/H7 -> 5.2429432
A8: Аудитории | B8: =1/D6 -> 1 | C8: =1/D7 -> 2 | D8: 1 | E8: 3 | F8: 2 | G8: =GEOMEAN(B8:F8) -> 1.6437518 | H8: =G8/SUM($G$6:$G$10) -> 0.29934985 | I8: =B8*$H$6+C8*$H$7+D8*$H$8+E8*$H$9+F8*$H$10 -> 1.5085816 | J8: =I8/H8 -> 5.0395268
A9: AR-гид | B9: =1/E6 -> 0.25 | C9: =1/E7 -> 0.5 | D9: =1/E8 -> 0.33333333 | E9: 1 | F9: =1/2 -> 0.5 | G9: =GEOMEAN(B9:F9) -> 0.46105396 | H9: =G9/SUM($G$6:$G$10) -> 0.083964275 | I9: =B9*$H$6+C9*$H$7+D9*$H$8+E9*$H$9+F9*$H$10 -> 0.42308228 | J9: =I9/H9 -> 5.0388368
A10: Рецепты | B10: =1/F6 -> 1 | C10: =1/F7 -> 0.5 | D10: =1/F8 -> 0.5 | E10: =1/F9 -> 2 | F10: 1 | G10: =GEOMEAN(B10:F10) -> 0.87055056 | H10: =G10/SUM($G$6:$G$10) -> 0.15853925 | I10: =B10*$H$6+C10*$H$7+D10*$H$8+E10*$H$9+F10*$H$10 -> 0.84323247 | J10: =I10/H10 -> 5.3187617
A11: λmax | B11: =AVERAGE(J6:J10) -> 5.1670252
A12: Индекс согласованности ИС | B12: =(B11-5)/(5-1) -> 0.041756303
A13: Отношение согласованности ОС | B13: =B12/'Концепции и критерии'!$C$38 -> 0.037282414 | C13: =IF(B13<=0.1,"согласована (ОС ≤ 10%)","требует пересмотра") -> согласована (ОС ≤ 10%)
A15: Эксперт: Алексей К.
A16: Альтернативы по критерию «Соответствие компетенциям» | B16: Сплит | C16: Репетиторы | D16: Аудитории | E16: AR-гид | F16: Рецепты | G16: Ср. геом. строки | H16: Вес w | I16: (A·w)ᵢ | J16: (A·w)ᵢ / wᵢ
A17: Сплит | B17: 1 | C17: 2 | D17: 1 | E17: 5 | F17: 2 | G17: =GEOMEAN(B17:F17) -> 1.8205642 | H17: =G17/SUM($G$17:$G$21) -> 0.30171354 | I17: =B17*$H$17+C17*$H$18+D17*$H$19+E17*$H$20+F17*$H$21 -> 1.5592407 | J17: =I17/H17 -> 5.1679507
A18: Репетиторы | B18: =1/C17 -> 0.5 | C18: 1 | D18: =1/2 -> 0.5 | E18: 4 | F18: =1/2 -> 0.5 | G18: =GEOMEAN(B18:F18) -> 0.87055056 | H18: =G18/SUM($G$17:$G$21) -> 0.14427225 | I18: =B18*$H$17+C18*$H$18+D18*$H$19+E18*$H$20+F18*$H$21 -> 0.72772923 | J18: =I18/H18 -> 5.0441386
A19: Аудитории | B19: =1/D17 -> 1 | C19: =1/D18 -> 2 | D19: 1 | E19: 6 | F19: 1 | G19: =GEOMEAN(B19:F19) -> 1.6437518 | H19: =G19/SUM($G$17:$G$21) -> 0.27241126 | I19: =B19*$H$17+C19*$H$18+D19*$H$19+E19*$H$20+F19*$H$21 -> 1.3665481 | J19: =I19/H19 -> 5.0164891
A20: AR-гид | B20: =1/E17 -> 0.2 | C20: =1/E18 -> 0.25 | D20: =1/E19 -> 0.16666667 | E20: 1 | F20: =1/6 -> 0.16666667 | G20: =GEOMEAN(B20:F20) -> 0.26824615 | H20: =G20/SUM($G$17:$G$21) -> 0.044455173 | I20: =B20*$H$17+C20*$H$18+D20*$H$19+E20*$H$20+F20*$H$21 -> 0.22579245 | J20: =I20/H20 -> 5.0791041
A21: Рецепты | B21: =1/F17 -> 0.5 | C21: =1/F18 -> 2 | D21: =1/F19 -> 1 | E21: =1/F20 -> 6 | F21: 1 | G21: =GEOMEAN(B21:F21) -> 1.4309691 | H21: =G21/SUM($G$17:$G$21) -> 0.23714778 | I21: =B21*$H$17+C21*$H$18+D21*$H$19+E21*$H$20+F21*$H$21 -> 1.2156913 | J21: =I21/H21 -> 5.126303
A22: λmax | B22: =AVERAGE(J17:J21) -> 5.0867971
A23: Индекс согласованности ИС | B23: =(B22-5)/(5-1) -> 0.021699274
A24: Отношение согласованности ОС | B24: =B23/'Концепции и критерии'!$C$38 -> 0.019374352 | C24: =IF(B24<=0.1,"согласована (ОС ≤ 10%)","требует пересмотра") -> согласована (ОС ≤ 10%)
A26: Эксперт: Александр Л.
A27: Альтернативы по критерию «Соответствие компетенциям» | B27: Сплит | C27: Репетиторы | D27: Аудитории | E27: AR-гид | F27: Рецепты | G27: Ср. геом. строки | H27: Вес w | I27: (A·w)ᵢ | J27: (A·w)ᵢ / wᵢ
A28: Сплит | B28: 1 | C28: 4 | D28: 2 | E28: 3 | F28: 2 | G28: =GEOMEAN(B28:F28) -> 2.1689435 | H28: =G28/SUM($G$28:$G$32) -> 0.38435228 | I28: =B28*$H$28+C28*$H$29+D28*$H$30+E28*$H$31+F28*$H$32 -> 1.9271869 | J28: =I28/H28 -> 5.014116
A29: Репетиторы | B29: =1/C28 -> 0.25 | C29: 1 | D29: =1/3 -> 0.33333333 | E29: 1 | F29: =1/2 -> 0.5 | G29: =GEOMEAN(B29:F29) -> 0.52961192 | H29: =G29/SUM($G$28:$G$32) -> 0.093851013 | I29: =B29*$H$28+C29*$H$29+D29*$H$30+E29*$H$31+F29*$H$32 -> 0.47596394 | J29: =I29/H29 -> 5.0714844
A30: Аудитории | B30: =1/D28 -> 0.5 | C30: =1/D29 -> 3 | D30: 1 | E30: 2 | F30: 1 | G30: =GEOMEAN(B30:F30) -> 1.2457309 | H30: =G30/SUM($G$28:$G$32) -> 0.22075242 | I30: =B30*$H$28+C30*$H$29+D30*$H$30+E30*$H$31+F30*$H$32 -> 1.119363 | J30: =I30/H30 -> 5.0706718
A31: AR-гид | B31: =1/E28 -> 0.33333333 | C31: =1/E29 -> 1 | D31: =1/E30 -> 0.5 | E31: 1 | F31: 1 | G31: =GEOMEAN(B31:F31) -> 0.69882712 | H31: =G31/SUM($G$28:$G$32) -> 0.12383715 | I31: =B31*$H$28+C31*$H$29+D31*$H$30+E31*$H$31+F31*$H$32 -> 0.63338894 | J31: =I31/H31 -> 5.1146923
A32: Рецепты | B32: =1/F28 -> 0.5 | C32: =1/F29 -> 2 | D32: =1/F30 -> 1 | E32: =1/F31 -> 1 | F32: 1 | G32: =GEOMEAN(B32:F32) -> 1 | H32: =G32/SUM($G$28:$G$32) -> 0.17720714 | I32: =B32*$H$28+C32*$H$29+D32*$H$30+E32*$H$31+F32*$H$32 -> 0.90167487 | J32: =I32/H32 -> 5.0882537
A33: λmax | B33: =AVERAGE(J28:J32) -> 5.0718436
A34: Индекс согласованности ИС | B34: =(B33-5)/(5-1) -> 0.017960904
A35: Отношение согласованности ОС | B35: =B34/'Концепции и критерии'!$C$38 -> 0.016036522 | C35: =IF(B35<=0.1,"согласована (ОС ≤ 10%)","требует пересмотра") -> согласована (ОС ≤ 10%)
A37: Коллективная матрица: поэлементное среднее геометрическое оценок трёх экспертов
A38: Альтернативы по критерию «Соответствие компетенциям» | B38: Сплит | C38: Репетиторы | D38: Аудитории | E38: AR-гид | F38: Рецепты | G38: Ср. геом. строки | H38: Вес w | I38: (A·w)ᵢ | J38: (A·w)ᵢ / wᵢ
A39: Сплит | B39: =GEOMEAN(B6,B17,B28) -> 1 | C39: =GEOMEAN(C6,C17,C28) -> 2.5198421 | D39: =GEOMEAN(D6,D17,D28) -> 1.259921 | E39: =GEOMEAN(E6,E17,E28) -> 3.9148676 | F39: =GEOMEAN(F6,F17,F28) -> 1.5874011 | G39: =GEOMEAN(B39:F39) -> 1.8156163 | H39: =G39/SUM($G$39:$G$43) -> 0.3239328 | I39: =B39*$H$39+C39*$H$40+D39*$H$41+E39*$H$42+F39*$H$43 -> 1.6216776 | J39: =I39/H39 -> 5.0062161
A40: Репетиторы | B40: =GEOMEAN(B7,B18,B29) -> 0.39685026 | C40: =GEOMEAN(C7,C18,C29) -> 1 | D40: =GEOMEAN(D7,D18,D29) -> 0.43679023 | E40: =GEOMEAN(E7,E18,E29) -> 2 | F40: =GEOMEAN(F7,F18,F29) -> 0.79370053 | G40: =GEOMEAN(B40:F40) -> 0.77253337 | H40: =G40/SUM($G$39:$G$43) -> 0.13783138 | I40: =B40*$H$39+C40*$H$40+D40*$H$41+E40*$H$42+F40*$H$43 -> 0.69330771 | J40: =I40/H40 -> 5.0301152
A41: Аудитории | B41: =GEOMEAN(B8,B19,B30) -> 0.79370053 | C41: =GEOMEAN(C8,C19,C30) -> 2.2894285 | D41: =GEOMEAN(D8,D19,D30) -> 1 | E41: =GEOMEAN(E8,E19,E30) -> 3.3019272 | F41: =GEOMEAN(F8,F19,F30) -> 1.259921 | G41: =GEOMEAN(B41:F41) -> 1.4986455 | H41: =G41/SUM($G$39:$G$43) -> 0.26738052 | I41: =B41*$H$39+C41*$H$40+D41*$H$41+E41*$H$42+F41*$H$43 -> 1.3423768 | J41: =I41/H41 -> 5.0204733
A42: AR-гид | B42: =GEOMEAN(B9,B20,B31) -> 0.25543648 | C42: =GEOMEAN(C9,C20,C31) -> 0.5 | D42: =GEOMEAN(D9,D20,D31) -> 0.30285343 | E42: =GEOMEAN(E9,E20,E31) -> 1 | F42: =GEOMEAN(F9,F20,F31) -> 0.43679023 | G42: =GEOMEAN(B42:F42) -> 0.44213171 | H42: =G42/SUM($G$39:$G$43) -> 0.078882836 | I42: =B42*$H$39+C42*$H$40+D42*$H$41+E42*$H$42+F42*$H$43 -> 0.39537158 | J42: =I42/H42 -> 5.012137
A43: Рецепты | B43: =GEOMEAN(B10,B21,B32) -> 0.62996052 | C43: =GEOMEAN(C10,C21,C32) -> 1.259921 | D43: =GEOMEAN(D10,D21,D32) -> 0.79370053 | E43: =GEOMEAN(E10,E21,E32) -> 2.2894285 | F43: =GEOMEAN(F10,F21,F32) -> 1 | G43: =GEOMEAN(B43:F43) -> 1.0759896 | H43: =G43/SUM($G$39:$G$43) -> 0.19197246 | I43: =B43*$H$39+C43*$H$40+D43*$H$41+E43*$H$42+F43*$H$43 -> 0.96251067 | J43: =I43/H43 -> 5.0137955
A44: λmax | B44: =AVERAGE(J39:J43) -> 5.0165474
...

Sheet Итог
A1: Синтез: глобальный вес альтернативы = Σ (локальный приоритет по критерию × вес критерия)
A3: Альтернатива | B3: Экономичность | C3: Актуальность | D3: Потенциал развития | E3: Простота реализации | F3: Соответствие компетенциям | G3: Глобальный вес | H3: Ранг
A4: Сплит | B4: =Экономичность!$H$39 -> 0.36275846 | C4: =Актуальность!$H$39 -> 0.22459673 | D4: ='Потенциал развития'!$H$39 -> 0.19361632 | E4: ='Простота реализации'!$H$39 -> 0.33755689 | F4: ='Соответствие компетенциям'!$H$39 -> 0.3239328 | G4: =SUMPRODUCT(B4:F4,$B$9:$F$9) -> 0.3050373 | H4: =RANK(G4,$G$4:$G$8,0) -> 1
A5: Репетиторы | B5: =Экономичность!$H$40 -> 0.079284349 | C5: =Актуальность!$H$40 -> 0.27019549 | D5: ='Потенциал развития'!$H$40 -> 0.31195309 | E5: ='Простота реализации'!$H$40 -> 0.093303537 | F5: ='Соответствие компетенциям'!$H$40 -> 0.13783138 | G5: =SUMPRODUCT(B5:F5,$B$9:$F$9) -> 0.15551513 | H5: =RANK(G5,$G$4:$G$8,0) -> 4
A6: Аудитории | B6: =Экономичность!$H$41 -> 0.21330026 | C6: =Актуальность!$H$41 -> 0.24166375 | D6: ='Потенциал развития'!$H$41 -> 0.098333077 | E6: ='Простота реализации'!$H$41 -> 0.21506978 | F6: ='Соответствие компетенциям'!$H$41 -> 0.26738052 | G6: =SUMPRODUCT(B6:F6,$B$9:$F$9) -> 0.21822047 | H6: =RANK(G6,$G$4:$G$8,0) -> 2
A7: AR-гид | B7: =Экономичность!$H$42 -> 0.060986841 | C7: =Актуальность!$H$42 -> 0.1817144 | D7: ='Потенциал развития'!$H$42 -> 0.28441465 | E7: ='Простота реализации'!$H$42 -> 0.057581796 | F7: ='Соответствие компетенциям'!$H$42 -> 0.078882836 | G7: =SUMPRODUCT(B7:F7,$B$9:$F$9) -> 0.11066406 | H7: =RANK(G7,$G$4:$G$8,0) -> 5
A8: Рецепты | B8: =Экономичность!$H$43 -> 0.28367009 | C8: =Актуальность!$H$43 -> 0.081829631 | D8: ='Потенциал развития'!$H$43 -> 0.11168286 | E8: ='Простота реализации'!$H$43 -> 0.29648799 | F8: ='Соответствие компетенциям'!$H$43 -> 0.19197246 | G8: =SUMPRODUCT(B8:F8,$B$9:$F$9) -> 0.21056305 | H8: =RANK(G8,$G$4:$G$8,0) -> 3
A9: Вес критерия | B9: =Критерии!$H$39 -> 0.27198522 | C9: =Критерии!$H$40 -> 0.18291805 | D9: =Критерии!$H$41 -> 0.10916692 | E9: =Критерии!$H$42 -> 0.21587481 | F9: =Критерии!$H$43 -> 0.22005499 | G9: =SUM(G4:G8) -> 1
A10: Лучшая концепция | B10: =INDEX($A$4:$A$8,MATCH(MAX($G$4:$G$8),$G$4:$G$8,0)) -> Сплит
A12: Проверка согласованности всех матриц (ОС ≤ 10%)
A13: Матрица | B13: Александр Ф. | C13: Алексей К. | D13: Александр Л. | E13: Коллективная
A14: Критерии | B14: =Критерии!$B$13 -> 0.06655409 | C14: =Критерии!$B$24 -> 0.030509581 | D14: =Критерии!$B$35 -> 0.01741842 | E14: =Критерии!$B$46 -> 0.010551964
A15: Альтернативы: Экономичность | B15: =Экономичность!$B$13 -> 0.015965071 | C15: =Экономичность!$B$24 -> 0.012322048 | D15: =Экономичность!$B$35 -> 0.018753253 | E15: =Экономичность!$B$46 -> 0.0089424629
A16: Альтернативы: Актуальность | B16: =Актуальность!$B$13 -> 0.020943725 | C16: =Актуальность!$B$24 -> 0.021749606 | D16: =Актуальность!$B$35 -> 0.012989466 | E16: =Актуальность!$B$46 -> 0.004171057
A17: Альтернативы: Потенциал развития | B17: ='Потенциал развития'!$B$13 -> 0.020484674 | C17: ='Потенциал развития'!$B$24 -> 0.017161647 | D17: ='Потенциал развития'!$B$35 -> 0.018905875 | E17: ='Потенциал развития'!$B$46 -> 0.0078381679
A18: Альтернативы: Простота реализации | B18: ='Простота реализации'!$B$13 -> 0.010464447 | C18: ='Простота реализации'!$B$24 -> 0.013843254 | D18: ='Простота реализации'!$B$35 -> 0.013096703 | E18: ='Простота реализации'!$B$46 -> 0.0050858821
A19: Альтернативы: Соответствие компетенциям | B19: ='Соответствие компетенциям'!$B$13 -> 0.037282414 | C19: ='Соответствие компетенциям'!$B$24 -> 0.019374352 | D19: ='Соответствие компетенциям'!$B$35 -> 0.016036522 | E19: ='Соответствие компетенциям'!$B$46 -> 0.0036936234
