Workbook

Sheet Концепции и критерии
A1: Фаза 1. Выбор концепции проекта — нечёткий коллективный TOPSIS
A3: № | B3: Короткое название | C3: Концепция проекта
A4: 1 | B4: Сплит | C4: Веб-приложение для учёта и разделения общих расходов в группе (поездки, съёмная квартира, мероприятия)
A5: 2 | B5: Репетиторы | C5: Онлайн-платформа поиска репетиторов с расписанием занятий и онлайн-оплатой
A6: 3 | B6: Аудитории | C6: Веб-сервис бронирования учебных аудиторий и переговорных комнат университета
A7: 4 | B7: AR-гид | C7: Мобильное приложение с AR-экскурсиями по историческому центру города
A8: 5 | B8: Рецепты | C8: Мобильное приложение подбора рецептов по имеющимся дома продуктам
A10: № | B10: Критерий | C10: Что оценивается (все критерии — «чем больше, тем лучше»)
A11: K1 | B11: Экономичность | C11: Затраты на разработку, инфраструктуру и сопровождение (чем выше оценка, тем дешевле проект)
A12: K2 | B12: Актуальность | C12: Востребованность продукта у целевой аудитории в данный момент
A13: K3 | B13: Потенциал развития | C13: Возможность масштабирования, добавления функций и монетизации
A14: K4 | B14: Простота реализации | C14: Техническая сложность и время до работающего MVP
A15: K5 | B15: Соответствие компетенциям | C15: Насколько стек технологий и предметная область знакомы команде
A17: № | B17: Эксперт | C17: Роль в оценке
A18: 1 | B18: Александр Ф. | C18: Участник команды, независимая экспертная оценка
A19: 2 | B19: Алексей К. | C19: Участник команды, независимая экспертная оценка
A20: 3 | B20: Александр Л. | C20: Участник команды, независимая экспертная оценка
B22: Обозначения:
C23: исходные данные (оценки экспертов) — можно менять
C24: итоговые результаты расчёта

Sheet Шкала
A1: Лингвистическая шкала → треугольные нечёткие числа (l, m, u)
A3: Оценка | B3: l | C3: m | D3: u
A4: Очень низкий | B4: 1 | C4: 1 | D4: 3
A5: Низкий | B5: 1 | C5: 3 | D5: 5
A6: Средний | B6: 3 | C6: 5 | D6: 7
A7: Высокий | B7: 5 | C7: 7 | D7: 9
A8: Очень высокий | B8: 7 | C8: 9 | D8: 9
A10: l — пессимистичная, m — наиболее ожидаемая, u — оптимистичная оценка. Той же шкалой задаётся важность критериев.

Sheet Оценки экспертов
A1: Этап 1. Лингвистические оценки экспертов (выпадающий список)
A3: Эксперт: Александр Ф.
A4: Альтернатива | B4: Экономичность | C4: Актуальность | D4: Потенциал развития | E4: Простота реализации | F4: Соответствие компетенциям
A5: Сплит | B5: Высокий | C5: Высокий | D5: Средний | E5: Очень высокий | F5: Очень высокий
A6: Репетиторы | B6: Низкий | C6: Очень высокий | D6: Очень высокий | E6: Низкий | F6: Средний
A7: Аудитории | B7: Средний | C7: Средний | D7: Низкий | E7: Средний | F7: Высокий
A8: AR-гид | B8: Очень низкий | C8: Средний | D8: Высокий | E8: Очень низкий | F8: Низкий
A9: Рецепты | B9: Высокий | C9: Низкий | D9: Средний | E9: Высокий | F9: Средний
A10: Важность критерия | B10: Высокий | C10: Средний | D10: Средний | E10: Очень высокий | F10: Высокий
A12: Эксперт: Алексей К.
A13: Альтернатива | B13: Экономичность | C13: Актуальность | D13: Потенциал развития | E13: Простота реализации | F13: Соответствие компетенциям
A14: Сплит | B14: Очень высокий | C14: Средний | D14: Средний | E14: Высокий | F14: Высокий
A15: Репетиторы | B15: Низкий | C15: Высокий | D15: Очень высокий | E15: Низкий | F15: Средний
A16: Аудитории | B16: Высокий | C16: Средний | D16: Низкий | E16: Высокий | F16: Высокий
A17: AR-гид | B17: Низкий | C17: Высокий | D17: Очень высокий | E17: Очень низкий | F17: Очень низкий
A18: Рецепты | B18: Высокий | C18: Средний | D18: Низкий | E18: Высокий | F18: Высокий
A19: Важность критерия | B19: Очень высокий | C19: Высокий | D19: Низкий | E19: Высокий | F19: Высокий
A21: Эксперт: Александр Л.
A22: Альтернатива | B22: Экономичность | C22: Актуальность | D22: Потенциал развития | E22: Простота реализации | F22: Соответствие компетенциям
A23: Сплит | B23: Высокий | C23: Высокий | D23: Высокий | E23: Высокий | F23: Очень высокий
A24: Репетиторы | B24: Очень низкий | C24: Высокий | D24: Высокий | E24: Низкий | F24: Низкий
A25: Аудитории | B25: Средний | C25: Высокий | D25: Средний | E25: Средний | F25: Средний
A26: AR-гид | B26: Очень низкий | C26: Средний | D26: Высокий | E26: Низкий | F26: Низкий
A27: Рецепты | B27: Очень высокий | C27: Низкий | D27: Средний | E27: Очень высокий | F27: Средний
A28: Важность критерия | B28: Высокий | C28: Средний | D28: Средний | E28: Высокий | F28: Очень высокий

Sheet Нечёткие оценки
A1: Этап 1 (продолжение). Перевод лингвистических оценок в нечёткие числа
A3: Эксперт: Александр Ф.
A4: Альтернатива | B4: Экономичность | E4: Актуальность | H4: Потенциал развития | K4: Простота реализации | N4: Соответствие компетенциям
B5: l | C5: m | D5: u | E5: l | F5: m | G5: u | H5: l | I5: m | J5: u | K5: l | L5: m | M5: u | N5: l | O5: m | P5: u
A6: Сплит | B6: =VLOOKUP('Оценки экспертов'!$B$5,Шкала!$A$4:$D$8,2,FALSE) -> 5 | C6: =VLOOKUP('Оценки экспертов'!$B$5,Шкала!$A$4:$D$8,3,FALSE) -> 7 | D6: =VLOOKUP('Оценки экспертов'!$B$5,Шкала!$A$4:$D$8,4,FALSE) -> 9 | E6: =VLOOKUP('Оценки экспертов'!$C$5,Шкала!$A$4:$D$8,2,FALSE) -> 5 | F6: =VLOOKUP('Оценки экспертов'!$C$5,Шкала!$A$4:$D$8,3,FALSE) -> 7 | G6: =VLOOKUP('Оценки экспертов'!$C$5,Шкала!$A$4:$D$8,4,FALSE) -> 9 | H6: =VLOOKUP('Оценки экспертов'!$D$5,Шкала!$A$4:$D$8,2,FALSE) -> 3 | I6: =VLOOKUP('Оценки экспертов'!$D$5,Шкала!$A$4:$D$8,3,FALSE) -> 5 | J6: =VLOOKUP('Оценки экспертов'!$D$5,Шкала!$A$4:$D$8,4,FALSE) -> 7 | K6: =VLOOKUP('Оценки экспертов'!$E$5,Шкала!$A$4:$D$8,2,FALSE) -> 7 | L6: =VLOOKUP('Оценки экспертов'!$E$5,Шкала!$A$4:$D$8,3,FALSE) -> 9 | M6: =VLOOKUP('Оценки экспертов'!$E$5,Шкала!$A$4:$D$8,4,FALSE) -> 9 | N6: =VLOOKUP('Оценки экспертов'!$F$5,Шкала!$A$4:$D$8,2,FALSE) -> 7 | O6: =VLOOKUP('Оценки экспертов'!$F$5,Шкала!$A$4:$D$8,3,FALSE) -> 9 | P6: =VLOOKUP('Оценки экспертов'!$F$5,Шкала!$A$4:$D$8,4,FALSE) -> 9
A7: Репетиторы | B7: =VLOOKUP('Оценки экспертов'!$B$6,Шкала!$A$4:$D$8,2,FALSE) -> 1 | C7: =VLOOKUP('Оценки экспертов'!$B$6,Шкала!$A$4:$D$8,3,FALSE) -> 3 | D7: =VLOOKUP('Оценки экспертов'!$B$6,Шкала!$A$4:$D$8,4,FALSE) -> 5 | E7: =VLOOKUP('Оценки экспертов'!$C$6,Шкала!$A$4:$D$8,2,FALSE) -> 7 | F7: =VLOOKUP('Оценки экспертов'!$C$6,Шкала!$A$4:$D$8,3,FALSE) -> 9 | G7: =VLOOKUP('Оценки экспертов'!$C$6,Шкала!$A$4:$D$8,4,FALSE) -> 9 | H7: =VLOOKUP('Оценки экспертов'!$D$6,Шкала!$A$4:$D$8,2,FALSE) -> 7 | I7: =VLOOKUP('Оценки экспертов'!$D$6,Шкала!$A$4:$D$8,3,FALSE) -> 9 | J7: =VLOOKUP('Оценки экспертов'!$D$6,Шкала!$A$4:$D$8,4,FALSE) -> 9 | K7: =VLOOKUP('Оценки экспертов'!$E$6,Шкала!$A$4:$D$8,2,FALSE) -> 1 | L7: =VLOOKUP('Оценки экспертов'!$E$6,Шкала!$A$4:$D$8,3,FALSE) -> 3 | M7: =VLOOKUP('Оценки экспертов'!$E$6,Шкала!$A$4:$D$8,4,FALSE) -> 5 | N7: =VLOOKUP('Оценки экспертов'!$F$6,Шкала!$A$4:$D$8,2,FALSE) -> 3 | O7: =VLOOKUP('Оценки экспертов'!$F$6,Шкала!$A$4:$D$8,3,FALSE) -> 5 | P7: =VLOOKUP('Оценки экспертов'!$F$6,Шкала!$A$4:$D$8,4,FALSE) -> 7
A8: Аудитории | B8: =VLOOKUP('Оценки экспертов'!$B$7,Шкала!$A$4:$D$8,2,FALSE) -> 3 | C8: =VLOOKUP('Оценки экспертов'!$B$7,Шкала!$A$4:$D$8,3,FALSE) -> 5 | D8: =VLOOKUP('Оценки экспертов'!$B$7,Шкала!$A$4:$D$8,4,FALSE) -> 7 | E8: =VLOOKUP('Оценки экспертов'!$C$7,Шкала!$A$4:$D$8,2,FALSE) -> 3 | F8: =VLOOKUP('Оценки экспертов'!$C$7,Шкала!$A$4:$D$8,3,FALSE) -> 5 | G8: =VLOOKUP('Оценки экспертов'!$C$7,Шкала!$A$4:$D$8,4,FALSE) -> 7 | H8: =VLOOKUP('Оценки экспертов'!$D$7,Шкала!$A$4:$D$8,2,FALSE) -> 1 | I8: =VLOOKUP('Оценки экспертов'!$D$7,Шкала!$A$4:$D$8,3,FALSE) -> 3 | J8: =VLOOKUP('Оценки экспертов'!$D$7,Шкала!$A$4:$D$8,4,FALSE) -> 5 | K8: =VLOOKUP('Оценки экспертов'!$E$7,Шкала!$A$4:$D$8,2,FALSE) -> 3 | L8: =VLOOKUP('Оценки экспертов'!$E$7,Шкала!$A$4:$D$8,3,FALSE) -> 5 | M8: =VLOOKUP('Оценки экспертов'!$E$7,Шкала!$A$4:$D$8,4,FALSE) -> 7 | N8: =VLOOKUP('Оценки экспертов'!$F$7,Шкала!$A$4:$D$8,2,FALSE) -> 5 | O8: =VLOOKUP('Оценки экспертов'!$F$7,Шкала!$A$4:$D$8,3,FALSE) -> 7 | P8: =VLOOKUP('Оценки экспертов'!$F$7,Шкала!$A$4:$D$8,4,FALSE) -> 9
A9: AR-гид | B9: =VLOOKUP('Оценки экспертов'!$B$8,Шкала!$A$4:$D$8,2,FALSE) -> 1 | C9: =VLOOKUP('Оценки экспертов'!$B$8,Шкала!$A$4:$D$8,3,FALSE) -> 1 | D9: =VLOOKUP('Оценки экспертов'!$B$8,Шкала!$A$4:$D$8,4,FALSE) -> 3 | E9: =VLOOKUP('Оценки экспертов'!$C$8,Шкала!$A$4:$D$8,2,FALSE) -> 3 | F9: =VLOOKUP('Оценки экспертов'!$C$8,Шкала!$A$4:$D$8,3,FALSE) -> 5 | G9: =VLOOKUP('Оценки экспертов'!$C$8,Шкала!$A$4:$D$8,4,FALSE) -> 7 | H9: =VLOOKUP('Оценки экспертов'!$D$8,Шкала!$A$4:$D$8,2,FALSE) -> 5 | I9: =VLOOKUP('Оценки экспертов'!$D$8,Шкала!$A$4:$D$8,3,FALSE) -> 7 | J9: =VLOOKUP('Оценки экспертов'!$D$8,Шкала!$A$4:$D$8,4,FALSE) -> 9 | K9: =VLOOKUP('Оценки экспертов'!$E$8,Шкала!$A$4:$D$8,2,FALSE) -> 1 | L9: =VLOOKUP('Оценки экспертов'!$E$8,Шкала!$A$4:$D$8,3,FALSE) -> 1 | M9: =VLOOKUP('Оценки экспертов'!$E$8,Шкала!$A$4:$D$8,4,FALSE) -> 3 | N9: =VLOOKUP('Оценки экспертов'!$F$8,Шкала!$A$4:$D$8,2,FALSE) -> 1 | O9: =VLOOKUP('Оценки экспертов'!$F$8,Шкала!$A$4:$D$8,3,FALSE) -> 3 | P9: =VLOOKUP('Оценки экспертов'!$F$8,Шкала!$A$4:$D$8,4,FALSE) -> 5
A10: Рецепты | B10: =VLOOKUP('Оценки экспертов'!$B$9,Шкала!$A$4:$D$8,2,FALSE) -> 5 | C10: =VLOOKUP('Оценки экспертов'!$B$9,Шкала!$A$4:$D$8,3,FALSE) -> 7 | D10: =VLOOKUP('Оценки экспертов'!$B$9,Шкала!$A$4:$D$8,4,FALSE) -> 9 | E10: =VLOOKUP('Оценки экспертов'!$C$9,Шкала!$A$4:$D$8,2,FALSE) -> 1 | F10: =VLOOKUP('Оценки экспертов'!$C$9,Шкала!$A$4:$D$8,3,FALSE) -> 3 | G10: =VLOOKUP('Оценки экспертов'!$C$9,Шкала!$A$4:$D$8,4,FALSE) -> 5 | H10: =VLOOKUP('Оценки экспертов'!$D$9,Шкала!$A$4:$D$8,2,FALSE) -> 3 | I10: =VLOOKUP('Оценки экспертов'!$D$9,Шкала!$A$4:$D$8,3,FALSE) -> 5 | J10: =VLOOKUP('Оценки экспертов'!$D$9,Шкала!$A$4:$D$8,4,FALSE) -> 7 | K10: =VLOOKUP('Оценки экспертов'!$E$9,Шкала!$A$4:$D$8,2,FALSE) -> 5 | L10: =VLOOKUP('Оценки экспертов'!$E$9,Шкала!$A$4:$D$8,3,FALSE) -> 7 | M10: =VLOOKUP('Оценки экспертов'!$E$9,Шкала!$A$4:$D$8,4,FALSE) -> 9 | N10: =VLOOKUP('Оценки экспертов'!$F$9,Шкала!$A$4:$D$8,2,FALSE) -> 3 | O10: =VLOOKUP('Оценки экспертов'!$F$9,Шкала!$A$4:$D$8,3,FALSE) -> 5 | P10: =VLOOKUP('Оценки экспертов'!$F$9,Шкала!$A$4:$D$8,4,FALSE) -> 7
A11: Важность критерия | B11: =VLOOKUP('Оценки экспертов'!$B$10,Шкала!$A$4:$D$8,2,FALSE) -> 5 | C11: =VLOOKUP('Оценки экспертов'!$B$10,Шкала!$A$4:$D$8,3,FALSE) -> 7 | D11: =VLOOKUP('Оценки экспертов'!$B$10,Шкала!$A$4:$D$8,4,FALSE) -> 9 | E11: =VLOOKUP('Оценки экспертов'!$C$10,Шкала!$A$4:$D$8,2,FALSE) -> 3 | F11: =VLOOKUP('Оценки экспертов'!$C$10,Шкала!$A$4:$D$8,3,FALSE) -> 5 | G11: =VLOOKUP('Оценки экспертов'!$C$10,Шкала!$A$4:$D$8,4,FALSE) -> 7 | H11: =VLOOKUP('Оценки экспертов'!$D$10,Шкала!$A$4:$D$8,2,FALSE) -> 3 | I11: =VLOOKUP('Оценки экспертов'!$D$10,Шкала!$A$4:$D$8,3,FALSE) -> 5 | J11: =VLOOKUP('Оценки экспертов'!$D$10,Шкала!$A$4:$D$8,4,FALSE) -> 7 | K11: =VLOOKUP('Оценки экспертов'!$E$10,Шкала!$A$4:$D$8,2,FALSE) -> 7 | L11: =VLOOKUP('Оценки экспертов'!$E$10,Шкала!$A$4:$D$8,3,FALSE) -> 9 | M11: =VLOOKUP('Оценки экспертов'!$E$10,Шкала!$A$4:$D$8,4,FALSE) -> 9 | N11: =VLOOKUP('Оценки экспертов'!$F$10,Шкала!$A$4:$D$8,2,FALSE) -> 5 | O11: =VLOOKUP('Оценки экспертов'!$F$10,Шкала!$A$4:$D$8,3,FALSE) -> 7 | P11: =VLOOKUP('Оценки экспертов'!$F$10,Шкала!$A$4:$D$8,4,FALSE) -> 9
A13: Эксперт: Алексей К.
A14: Альтернатива | B14: Экономичность | E14: Актуальность | H14: Потенциал развития | K14: Простота реализации | N14: Соответствие компетенциям
B15: l | C15: m | D15: u | E15: l | F15: m | G15: u | H15: l | I15: m | J15: u | K15: l | L15: m | M15: u | N15: l | O15: m | P15: u
A16: Сплит | B16: =VLOOKUP('Оценки экспертов'!$B$14,Шкала!$A$4:$D$8,2,FALSE) -> 7 | C16: =VLOOKUP('Оценки экспертов'!$B$14,Шкала!$A$4:$D$8,3,FALSE) -> 9 | D16: =VLOOKUP('Оценки экспертов'!$B$14,Шкала!$A$4:$D$8,4,FALSE) -> 9 | E16: =VLOOKUP('Оценки экспертов'!$C$14,Шкала!$A$4:$D$8,2,FALSE) -> 3 | F16: =VLOOKUP('Оценки экспертов'!$C$14,Шкала!$A$4:$D$8,3,FALSE) -> 5 | G16: =VLOOKUP('Оценки экспертов'!$C$14,Шкала!$A$4:$D$8,4,FALSE) -> 7 | H16: =VLOOKUP('Оценки экспертов'!$D$14,Шкала!$A$4:$D$8,2,FALSE) -> 3 | I16: =VLOOKUP('Оценки экспертов'!$D$14,Шкала!$A$4:$D$8,3,FALSE) -> 5 | J16: =VLOOKUP('Оценки экспертов'!$D$14,Шкала!$A$4:$D$8,4,FALSE) -> 7 | K16: =VLOOKUP('Оценки экспертов'!$E$14,Шкала!$A$4:$D$8,2,FALSE) -> 5 | L16: =VLOOKUP('Оценки экспертов'!$E$14,Шкала!$A$4:$D$8,3,FALSE) -> 7 | M16: =VLOOKUP('Оценки экспертов'!$E$14,Шкала!$A$4:$D$8,4,FALSE) -> 9 | N16: =VLOOKUP('Оценки экспертов'!$F$14,Шкала!$A$4:$D$8,2,FALSE) -> 5 | O16: =VLOOKUP('Оценки экспертов'!$F$14,Шкала!$A$4:$D$8,3,FALSE) -> 7 | P16: =VLOOKUP('Оценки экспертов'!$F$14,Шкала!$A$4:$D$8,4,FALSE) -> 9
A17: Репетиторы | B17: =VLOOKUP('Оценки экспертов'!$B$15,Шкала!$A$4:$D$8,2,FALSE) -> 1 | C17: =VLOOKUP('Оценки экспертов'!$B$15,Шкала!$A$4:$D$8,3,FALSE) -> 3 | D17: =VLOOKUP('Оценки экспертов'!$B$15,Шкала!$A$4:$D$8,4,FALSE) -> 5 | E17: =VLOOKUP('Оценки экспертов'!$C$15,Шкала!$A$4:$D$8,2,FALSE) -> 5 | F17: =VLOOKUP('Оценки экспертов'!$C$15,Шкала!$A$4:$D$8,3,FALSE) -> 7 | G17: =VLOOKUP('Оценки экспертов'!$C$15,Шкала!$A$4:$D$8,4,FALSE) -> 9 | H17: =VLOOKUP('Оценки экспертов'!$D$15,Шкала!$A$4:$D$8,2,FALSE) -> 7 | I17: =VLOOKUP('Оценки экспертов'!$D$15,Шкала!$A$4:$D$8,3,FALSE) -> 9 | J17: =VLOOKUP('Оценки экспертов'!$D$15,Шкала!$A$4:$D$8,4,FALSE) -> 9 | K17: =VLOOKUP('Оценки экспертов'!$E$15,Шкала!$A$4:$D$8,2,FALSE) -> 1 | L17: =VLOOKUP('Оценки экспертов'!$E$15,Шкала!$A$4:$D$8,3,FALSE) -> 3 | M17: =VLOOKUP('Оценки экспертов'!$E$15,Шкала!$A$4:$D$8,4,FALSE) -> 5 | N17: =VLOOKUP('Оценки экспертов'!$F$15,Шкала!$A$4:$D$8,2,FALSE) -> 3 | O17: =VLOOKUP('Оценки экспертов'!$F$15,Шкала!$A$4:$D$8,3,FALSE) -> 5 | P17: =VLOOKUP('Оценки экспертов'!$F$15,Шкала!$A$4:$D$8,4,FALSE) -> 7
A18: Аудитории | B18: =VLOOKUP('Оценки экспертов'!$B$16,Шкала!$A$4:$D$8,2,FALSE) -> 5 | C18: =VLOOKUP('Оценки экспертов'!$B$16,Шкала!$A$4:$D$8,3,FALSE) -> 7 | D18: =VLOOKUP('Оценки экспертов'!$B$16,Шкала!$A$4:$D$8,4,FALSE) -> 9 | E18: =VLOOKUP('Оценки экспертов'!$C$16,Шкала!$A$4:$D$8,2,FALSE) -> 3 | F18: =VLOOKUP('Оценки экспертов'!$C$16,Шкала!$A$4:$D$8,3,FALSE) -> 5 | G18: =VLOOKUP('Оценки экспертов'!$C$16,Шкала!$A$4:$D$8,4,FALSE) -> 7 | H18: =VLOOKUP('Оценки экспертов'!$D$16,Шкала!$A$4:$D$8,2,FALSE) -> 1 | I18: =VLOOKUP('Оценки экспертов'!$D$16,Шкала!$A$4:$D$8,3,FALSE) -> 3 | J18: =VLOOKUP('Оценки экспертов'!$D$16,Шкала!$A$4:$D$8,4,FALSE) -> 5 | K18: =VLOOKUP('Оценки экспертов'!$E$16,Шкала!$A$4:$D$8,2,FALSE) -> 5 | L18: =VLOOKUP('Оценки экспертов'!$E$16,Шкала!$A$4:$D$8,3,FALSE) -> 7 | M18: =VLOOKUP('Оценки экспертов'!$E$16,Шкала!$A$4:$D$8,4,FALSE) -> 9 | N18: =VLOOKUP('Оценки экспертов'!$F$16,Шкала!$A$4:$D$8,2,FALSE) -> 5 | O18: =VLOOKUP('Оценки экспертов'!$F$16,Шкала!$A$4:$D$8,3,FALSE) -> 7 | P18: =VLOOKUP('Оценки экспертов'!$F$16,Шкала!$A$4:$D$8,4,FALSE) -> 9
A19: AR-гид | B19: =VLOOKUP('Оценки экспертов'!$B$17,Шкала!$A$4:$D$8,2,FALSE) -> 1 | C19: =VLOOKUP('Оценки экспертов'!$B$17,Шкала!$A$4:$D$8,3,FALSE) -> 3 | D19: =VLOOKUP('Оценки экспертов'!$B$17,Шкала!$A$4:$D$8,4,FALSE) -> 5 | E19: =VLOOKUP('Оценки экспертов'!$C$17,Шкала!$A$4:$D$8,2,FALSE) -> 5 | F19: =VLOOKUP('Оценки экспертов'!$C$17,Шкала!$A$4:$D$8,3,FALSE) -> 7 | G19: =VLOOKUP('Оценки экспертов'!$C$17,Шкала!$A$4:$D$8,4,FALSE) -> 9 | H19: =VLOOKUP('Оценки экспертов'!$D$17,Шкала!$A$4:$D$8,2,FALSE) -> 7 | I19: =VLOOKUP('Оценки экспертов'!$D$17,Шкала!$A$4:$D$8,3,FALSE) -> 9 | J19: =VLOOKUP('Оценки экспертов'!$D$17,Шкала!$A$4:$D$8,4,FALSE) -> 9 | K19: =VLOOKUP('Оценки экспертов'!$E$17,Шкала!$A$4:$D$8,2,FALSE) -> 1 | L19: =VLOOKUP('Оценки экспертов'!$E$17,Шкала!$A$4:$D$8,3,FALSE) -> 1 | M19: =VLOOKUP('Оценки экспертов'!$E$17,Шкала!$A$4:$D$8,4,FALSE) -> 3 | N19: =VLOOKUP('Оценки экспертов'!$F$17,Шкала!$A$4:$D$8,2,FALSE) -> 1 | O19: =VLOOKUP('Оценки экспертов'!$F$17,Шкала!$A$4:$D$8,3,FALSE) -> 1 | P19: =VLOOKUP('Оценки экспертов'!$F$17,Шкала!$A$4:$D$8,4,FALSE) -> 3
A20: Рецепты | B20: =VLOOKUP('Оценки экспертов'!$B$18,Шкала!$A$4:$D$8,2,FALSE) -> 5 | C20: =VLOOKUP('Оценки экспертов'!$B$18,Шкала!$A$4:$D$8,3,FALSE) -> 7 | D20: =VLOOKUP('Оценки экспертов'!$B$18,Шкала!$A$4:$D$8,4,FALSE) -> 9 | E20: =VLOOKUP('Оценки экспертов'!$C$18,Шкала!$A$4:$D$8,2,FALSE) -> 3 | F20: =VLOOKUP('Оценки экспертов'!$C$18,Шкала!$A$4:$D$8,3,FALSE) -> 5 | G20: =VLOOKUP('Оценки экспертов'!$C$18,Шкала!$A$4:$D$8,4,FALSE) -> 7 | H20: =VLOOKUP('Оценки экспертов'!$D$18,Шкала!$A$4:$D$8,2,FALSE) -> 1 | I20: =VLOOKUP('Оценки экспертов'!$D$18,Шкала!$A$4:$D$8,3,FALSE) -> 3 | J20: =VLOOKUP('Оценки экспертов'!$D$18,Шкала!$A$4:$D$8,4,FALSE) -> 5 | K20: =VLOOKUP('Оценки экспертов'!$E$18,Шкала!$A$4:$D$8,2,FALSE) -> 5 | L20: =VLOOKUP('Оценки экспертов'!$E$18,Шкала!$A$4:$D$8,3,FALSE) -> 7 | M20: =VLOOKUP('Оценки экспертов'!$E$18,Шкала!$A$4:$D$8,4,FALSE) -> 9 | N20: =VLOOKUP('Оценки экспертов'!$F$18,Шкала!$A$4:$D$8,2,FALSE) -> 5 | O20: =VLOOKUP('Оценки экспертов'!$F$18,Шкала!$A$4:$D$8,3,FALSE) -> 7 | P20: =VLOOKUP('Оценки экспертов'!$F$18,Шкала!$A$4:$D$8,4,FALSE) -> 9
A21: Важность критерия | B21: =VLOOKUP('Оценки экспертов'!$B$19,Шкала!$A$4:$D$8,2,FALSE) -> 7 | C21: =VLOOKUP('Оценки экспертов'!$B$19,Шкала!$A$4:$D$8,3,FALSE) -> 9 | D21: =VLOOKUP('Оценки экспертов'!$B$19,Шкала!$A$4:$D$8,4,FALSE) -> 9 | E21: =VLOOKUP('Оценки экспертов'!$C$19,Шкала!$A$4:$D$8,2,FALSE) -> 5 | F21: =VLOOKUP('Оценки экспертов'!$C$19,Шкала!$A$4:$D$8,3,FALSE) -> 7 | G21: =VLOOKUP('Оценки экспертов'!$C$19,Шкала!$A$4:$D$8,4,FALSE) -> 9 | H21: =VLOOKUP('Оценки экспертов'!$D$19,Шкала!$A$4:$D$8,2,FALSE) -> 1 | I21: =VLOOKUP('Оценки экспертов'!$D$19,Шкала!$A$4:$D$8,3,FALSE) -> 3 | J21: =VLOOKUP('Оценки экспертов'!$D$19,Шкала!$A$4:$D$8,4,FALSE) -> 5 | K21: =VLOOKUP('Оценки экспертов'!$E$19,Шкала!$A$4:$D$8,2,FALSE) -> 5 | L21: =VLOOKUP('Оценки экспертов'!$E$19,Шкала!$A$4:$D$8,3,FALSE) -> 7 | M21: =VLOOKUP('Оценки экспертов'!$E$19,Шкала!$A$4:$D$8,4,FALSE) -> 9 | N21: =VLOOKUP('Оценки экспертов'!$F$19,Шкала!$A$4:$D$8,2,FALSE) -> 5 | O21: =VLOOKUP('Оценки экспертов'!$F$19,Шкала!$A$4:$D$8,3,FALSE) -> 7 | P21: =VLOOKUP('Оценки экспертов'!$F$19,Шкала!$A$4:$D$8,4,FALSE) -> 9
A23: Эксперт: Александр Л.
A24: Альтернатива | B24: Экономичность | E24: Актуальность | H24: Потенциал развития | K24: Простота реализации | N24: Соответствие компетенциям
B25: l | C25: m | D25: u | E25: l | F25: m | G25: u | H25: l | I25: m | J25: u | K25: l | L25: m | M25: u | N25: l | O25: m | P25: u
A26: Сплит | B26: =VLOOKUP('Оценки экспертов'!$B$23,Шкала!$A$4:$D$8,2,FALSE) -> 5 | C26: =VLOOKUP('Оценки экспертов'!$B$23,Шкала!$A$4:$D$8,3,FALSE) -> 7 | D26: =VLOOKUP('Оценки экспертов'!$B$23,Шкала!$A$4:$D$8,4,FALSE) -> 9 | E26: =VLOOKUP('Оценки экспертов'!$C$23,Шкала!$A$4:$D$8,2,FALSE) -> 5 | F26: =VLOOKUP('Оценки экспертов'!$C$23,Шкала!$A$4:$D$8,3,FALSE) -> 7 | G26: =VLOOKUP('Оценки экспертов'!$C$23,Шкала!$A$4:$D$8,4,FALSE) -> 9 | H26: =VLOOKUP('Оценки экспертов'!$D$23,Шкала!$A$4:$D$8,2,FALSE) -> 5 | I26: =VLOOKUP('Оценки экспертов'!$D$23,Шкала!$A$4:$D$8,3,FALSE) -> 7 | J26: =VLOOKUP('Оценки экспертов'!$D$23,Шкала!$A$4:$D$8,4,FALSE) -> 9 | K26: =VLOOKUP('Оценки экспертов'!$E$23,Шкала!$A$4:$D$8,2,FALSE) -> 5 | L26: =VLOOKUP('Оценки экспертов'!$E$23,Шкала!$A$4:$D$8,3,FALSE) -> 7 | M26: =VLOOKUP('Оценки экспертов'!$E$23,Шкала!$A$4:$D$8,4,FALSE) -> 9 | N26: =VLOOKUP('Оценки экспертов'!$F$23,Шкала!$A$4:$D$8,2,FALSE) -> 7 | O26: =VLOOKUP('Оценки экспертов'!$F$23,Шкала!$A$4:$D$8,3,FALSE) -> 9 | P26: =VLOOKUP('Оценки экспертов'!$F$23,Шкала!$A$4:$D$8,4,FALSE) -> 9
A27: Репетиторы | B27: =VLOOKUP('Оценки экспертов'!$B$24,Шкала!$A$4:$D$8,2,FALSE) -> 1 | C27: =VLOOKUP('Оценки экспертов'!$B$24,Шкала!$A$4:$D$8,3,FALSE) -> 1 | D27: =VLOOKUP('Оценки экспертов'!$B$24,Шкала!$A$4:$D$8,4,FALSE) -> 3 | E27: =VLOOKUP('Оценки экспертов'!$C$24,Шкала!$A$4:$D$8,2,FALSE) -> 5 | F27: =VLOOKUP('Оценки экспертов'!$C$24,Шкала!$A$4:$D$8,3,FALSE) -> 7 | G27: =VLOOKUP('Оценки экспертов'!$C$24,Шкала!$A$4:$D$8,4,FALSE) -> 9 | H27: =VLOOKUP('Оценки экспертов'!$D$24,Шкала!$A$4:$D$8,2,FALSE) -> 5 | I27: =VLOOKUP('Оценки экспертов'!$D$24,Шкала!$A$4:$D$8,3,FALSE) -> 7 | J27: =VLOOKUP('Оценки экспертов'!$D$24,Шкала!$A$4:$D$8,4,FALSE) -> 9 | K27: =VLOOKUP('Оценки экспертов'!$E$24,Шкала!$A$4:$D$8,2,FALSE) -> 1 | L27: =VLOOKUP('Оценки экспертов'!$E$24,Шкала!$A$4:$D$8,3,FALSE) -> 3 | M27: =VLOOKUP('Оценки экспертов'!$E$24,Шкала!$A$4:$D$8,4,FALSE) -> 5 | N27: =VLOOKUP('Оценки экспертов'!$F$24,Шкала!$A$4:$D$8,2,FALSE) -> 1 | O27: =VLOOKUP('Оценки экспертов'!$F$24,Шкала!$A$4:$D$8,3,FALSE) -> 3 | P27: =VLOOKUP('Оценки экспертов'!$F$24,Шкала!$A$4:$D$8,4,FALSE) -> 5
A28: Аудитории | B28: =VLOOKUP('Оценки экспертов'!$B$25,Шкала!$A$4:$D$8,2,FALSE) -> 3 | C28: =VLOOKUP('Оценки экспертов'!$B$25,Шкала!$A$4:$D$8,3,FALSE) -> 5 | D28: =VLOOKUP('Оценки экспертов'!$B$25,Шкала!$A$4:$D$8,4,FALSE) -> 7 | E28: =VLOOKUP('Оценки экспертов'!$C$25,Шкала!$A$4:$D$8,2,FALSE) -> 5 | F28: =VLOOKUP('Оценки экспертов'!$C$25,Шкала!$A$4:$D$8,3,FALSE) -> 7 | G28: =VLOOKUP('Оценки экспертов'!$C$25,Шкала!$A$4:$D$8,4,FALSE) -> 9 | H28: =VLOOKUP('Оценки экспертов'!$D$25,Шкала!$A$4:$D$8,2,FALSE) -> 3 | I28: =VLOOKUP('Оценки экспертов'!$D$25,Шкала!$A$4:$D$8,3,FALSE) -> 5 | J28: =VLOOKUP('Оценки экспертов'!$D$25,Шкала!$A$4:$D$8,4,FALSE) -> 7 | K28: =VLOOKUP('Оценки экспертов'!$E$25,Шкала!$A$4:$D$8,2,FALSE) -> 3 | L28: =VLOOKUP('Оценки экспертов'!$E$25,Шкала!$A$4:$D$8,3,FALSE) -> 5 | M28: =VLOOKUP('Оценки экспертов'!$E$25,Шкала!$A$4:$D$8,4,FALSE) -> 7 | N28: =VLOOKUP('Оценки экспертов'!$F$25,Шкала!$A$4:$D$8,2,FALSE) -> 3 | O28: =VLOOKUP('Оценки экспертов'!$F$25,Шкала!$A$4:$D$8,3,FALSE) -> 5 | P28: =VLOOKUP('Оценки экспертов'!$F$25,Шкала!$A$4:$D$8,4,FALSE) -> 7
A29: AR-гид | B29: =VLOOKUP('Оценки экспертов'!$B$26,Шкала!$A$4:$D$8,2,FALSE) -> 1 | C29: =VLOOKUP('Оценки экспертов'!$B$26,Шкала!$A$4:$D$8,3,FALSE) -> 1 | D29: =VLOOKUP('Оценки экспертов'!$B$26,Шкала!$A$4:$D$8,4,FALSE) -> 3 | E29: =VLOOKUP('Оценки экспертов'!$C$26,Шкала!$A$4:$D$8,2,FALSE) -> 3 | F29: =VLOOKUP('Оценки экспертов'!$C$26,Шкала!$A$4:$D$8,3,FALSE) -> 5 | G29: =VLOOKUP('Оценки экспертов'!$C$26,Шкала!$A$4:$D$8,4,FALSE) -> 7 | H29: =VLOOKUP('Оценки экспертов'!$D$26,Шкала!$A$4:$D$8,2,FALSE) -> 5 | I29: =VLOOKUP('Оценки экспертов'!$D$26,Шкала!$A$4:$D$8,3,FALSE) -> 7 | J29: =VLOOKUP('Оценки экспертов'!$D$26,Шкала!$A$4:$D$8,4,FALSE) -> 9 | K29: =VLOOKUP('Оценки экспертов'!$E$26,Шкала!$A$4:$D$8,2,FALSE) -> 1 | L29: =VLOOKUP('Оценки экспертов'!$E$26,Шкала!$A$4:$D$8,3,FALSE) -> 3 | M29: =VLOOKUP('Оценки экспертов'!$E$26,Шкала!$A$4:$D$8,4,FALSE) -> 5 | N29: =VLOOKUP('Оценки экспертов'!$F$26,Шкала!$A$4:$D$8,2,FALSE) -> 1 | O29: =VLOOKUP('Оценки экспертов'!$F$26,Шкала!$A$4:$D$8,3,FALSE) -> 3 | P29: =VLOOKUP('Оценки экспертов'!$F$26,Шкала!$A$4:$D$8,4,FALSE) -> 5
A30: Рецепты | B30: =VLOOKUP('Оценки экспертов'!$B$27,Шкала!$A$4:$D$8,2,FALSE) -> 7 | C30: =VLOOKUP('Оценки экспертов'!$B$27,Шкала!$A$4:$D$8,3,FALSE) -> 9 | D30: =VLOOKUP('Оценки экспертов'!$B$27,Шкала!$A$4:$D$8,4,FALSE) -> 9 | E30: =VLOOKUP('Оценки экспертов'!$C$27,Шкала!$A$4:$D$8,2,FALSE) -> 1 | F30: =VLOOKUP('Оценки экспертов'!$C$27,Шкала!$A$4:$D$8,3,FALSE) -> 3 | G30: =VLOOKUP('Оценки экспертов'!$C$27,Шкала!$A$4:$D$8,4,FALSE) -> 5 | H30: =VLOOKUP('Оценки экспертов'!$D$27,Шкала!$A$4:$D$8,2,FALSE) -> 3 | I30: =VLOOKUP('Оценки экспертов'!$D$27,Шкала!$A$4:$D$8,3,FALSE) -> 5 | J30: =VLOOKUP('Оценки экспертов'!$D$27,Шкала!$A$4:$D$8,4,FALSE) -> 7 | K30: =VLOOKUP('Оценки экспертов'!$E$27,Шкала!$A$4:$D$8,2,FALSE) -> 7 | L30: =VLOOKUP('Оценки экспертов'!$E$27,Шкала!$A$4:$D$8,3,FALSE) -> 9 | M30: =VLOOKUP('Оценки экспертов'!$E$27,Шкала!$A$4:$D$8,4,FALSE) -> 9 | N30: =VLOOKUP('Оценки экспертов'!$F$27,Шкала!$A$4:$D$8,2,FALSE) -> 3 | O30: =VLOOKUP('Оценки экспертов'!$F$27,Шкала!$A$4:$D$8,3,FALSE) -> 5 | P30: =VLOOKUP('Оценки экспертов'!$F$27,Шкала!$A$4:$D$8,4,FALSE) -> 7
A31: Важность критерия | B31: =VLOOKUP('Оценки экспертов'!$B$28,Шкала!$A$4:$D$8,2,FALSE) -> 5 | C31: =VLOOKUP('Оценки экспертов'!$B$28,Шкала!$A$4:$D$8,3,FALSE) -> 7 | D31: =VLOOKUP('Оценки экспертов'!$B$28,Шкала!$A$4:$D$8,4,FALSE) -> 9 | E31: =VLOOKUP('Оценки экспертов'!$C$28,Шкала!$A$4:$D$8,2,FALSE) -> 3 | F31: =VLOOKUP('Оценки экспертов'!$C$28,Шкала!$A$4:$D$8,3,FALSE) -> 5 | G31: =VLOOKUP('Оценки экспертов'!$C$28,Шкала!$A$4:$D$8,4,FALSE) -> 7 | H31: =VLOOKUP('Оценки экспертов'!$D$28,Шкала!$A$4:$D$8,2,FALSE) -> 3 | I31: =VLOOKUP('Оценки экспертов'!$D$28,Шкала!$A$4:$D$8,3,FALSE) -> 5 | J31: =VLOOKUP('Оценки экспертов'!$D$28,Шкала!$A$4:$D$8,4,FALSE) -> 7 | K31: =VLOOKUP('Оценки экспертов'!$E$28,Шкала!$A$4:$D$8,2,FALSE) -> 5 | L31: =VLOOKUP('Оценки экспертов'!$E$28,Шкала!$A$4:$D$8,3,FALSE) -> 7 | M31: =VLOOKUP('Оценки экспертов'!$E$28,Шкала!$A$4:$D$8,4,FALSE) -> 9 | N31: =VLOOKUP('Оценки экспертов'!$F$28,Шкала!$A$4:$D$8,2,FALSE) -> 7 | O31: =VLOOKUP('Оценки экспертов'!$F$28,Шкала!$A$4:$D$8,3,FALSE) -> 9 | P31: =VLOOKUP('Оценки экспертов'!$F$28,Шкала!$A$4:$D$8,4,FALSE) -> 9

Sheet Расчёт
A1: Этап 2. Агрегация оценок экспертов: l = min, m = среднее, u = max
A2: Альтернатива | B2: Экономичность | E2: Актуальность | H2: Потенциал развития | K2: Простота реализации | N2: Соответствие компетенциям
B3: l | C3: m | D3: u | E3: l | F3: m | G3: u | H3: l | I3: m | J3: u | K3: l | L3: m | M3: u | N3: l | O3: m | P3: u
A4: Сплит | B4: =MIN('Нечёткие оценки'!B6,'Нечёткие оценки'!B16,'Нечёткие оценки'!B26) -> 5 | C4: =AVERAGE('Нечёткие оценки'!C6,'Нечёткие оценки'!C16,'Нечёткие оценки'!C26) -> 7.6666667 | D4: =MAX('Нечёткие оценки'!D6,'Нечёткие оценки'!D16,'Нечёткие оценки'!D26) -> 9 | E4: =MIN('Нечёткие оценки'!E6,'Нечёткие оценки'!E16,'Нечёткие оценки'!E26) -> 3 | F4: =AVERAGE('Нечёткие оценки'!F6,'Нечёткие оценки'!F16,'Нечёткие оценки'!F26) -> 6.3333333 | G4: =MAX('Нечёткие оценки'!G6,'Нечёткие оценки'!G16,'Нечёткие оценки'!G26) -> 9 | H4: =MIN('Нечёткие оценки'!H6,'Нечёткие оценки'!H16,'Нечёткие оценки'!H26) -> 3 | I4: =AVERAGE('Нечёткие оценки'!I6,'Нечёткие оценки'!I16,'Нечёткие оценки'!I26) -> 5.6666667 | J4: =MAX('Нечёткие оценки'!J6,'Нечёткие оценки'!J16,'Нечёткие оценки'!J26) -> 9 | K4: =MIN('Нечёткие оценки'!K6,'Нечёткие оценки'!K16,'Нечёткие оценки'!K26) -> 5 | L4: =AVERAGE('Нечёткие оценки'!L6,'Нечёткие оценки'!L16,'Нечёткие оценки'!L26) -> 7.6666667 | M4: =MAX('Нечёткие оценки'!M6,'Нечёткие оценки'!M16,'Нечёткие оценки'!M26) -> 9 | N4: =MIN('Нечёткие оценки'!N6,'Нечёткие оценки'!N16,'Нечёткие оценки'!N26) -> 5 | O4: =AVERAGE('Нечёткие оценки'!O6,'Нечёткие оценки'!O16,'Нечёткие оценки'!O26) -> 8.3333333 | P4: =MAX('Нечёткие оценки'!P6,'Нечёткие оценки'!P16,'Нечёткие оценки'!P26) -> 9
A5: Репетиторы | B5: =MIN('Нечёткие оценки'!B7,'Нечёткие оценки'!B17,'Нечёткие оценки'!B27) -> 1 | C5: =AVERAGE('Нечёткие оценки'!C7,'Нечёткие оценки'!C17,'Нечёткие оценки'!C27) -> 2.3333333 | D5: =MAX('Нечёткие оценки'!D7,'Нечёткие оценки'!D17,'Нечёткие оценки'!D27) -> 5 | E5: =MIN('Нечёткие оценки'!E7,'Нечёткие оценки'!E17,'Нечёткие оценки'!E27) -> 5 | F5: =AVERAGE('Нечёткие оценки'!F7,'Нечёткие оценки'!F17,'Нечёткие оценки'!F27) -> 7.6666667 | G5: =MAX('Нечёткие оценки'!G7,'Нечёткие оценки'!G17,'Нечёткие оценки'!G27) -> 9 | H5: =MIN('Нечёткие оценки'!H7,'Нечёткие оценки'!H17,'Нечёткие оценки'!H27) -> 5 | I5: =AVERAGE('Нечёткие оценки'!I7,'Нечёткие оценки'!I17,'Нечёткие оценки'!I27) -> 8.3333333 | J5: =MAX('Нечёткие оценки'!J7,'Нечёткие оценки'!J17,'Нечёткие оценки'!J27) -> 9 | K5: =MIN('Нечёткие оценки'!K7,'Нечёткие оценки'!K17,'Нечёткие оценки'!K27) -> 1 | L5: =AVERAGE('Нечёткие оценки'!L7,'Нечёткие оценки'!L17,'Нечёткие оценки'!L27) -> 3 | M5: =MAX('Нечёткие оценки'!M7,'Нечёткие оценки'!M17,'Нечёткие оценки'!M27) -> 5 | N5: =MIN('Нечёткие оценки'!N7,'Нечёткие оценки'!N17,'Нечёткие оценки'!N27) -> 1 | O5: =AVERAGE('Нечёткие оценки'!O7,'Нечёткие оценки'!O17,'Нечёткие оценки'!O27) -> 4.3333333 | P5: =MAX('Нечёткие оценки'!P7,'Нечёткие оценки'!P17,'Нечёткие оценки'!P27) -> 7
A6: Аудитории | B6: =MIN('Нечёткие оценки'!B8,'Нечёткие оценки'!B18,'Нечёткие оценки'!B28) -> 3 | C6: =AVERAGE('Нечёткие оценки'!C8,'Нечёткие оценки'!C18,'Нечёткие оценки'!C28) -> 5.6666667 | D6: =MAX('Нечёткие оценки'!D8,'Нечёткие оценки'!D18,'Нечёткие оценки'!D28) -> 9 | E6: =MIN('Нечёткие оценки'!E8,'Нечёткие оценки'!E18,'Нечёткие оценки'!E28) -> 3 | F6: =AVERAGE('Нечёткие оценки'!F8,'Нечёткие оценки'!F18,'Нечёткие оценки'!F28) -> 5.6666667 | G6: =MAX('Нечёткие оценки'!G8,'Нечёткие оценки'!G18,'Нечёткие оценки'!G28) -> 9 | H6: =MIN('Нечёткие оценки'!H8,'Нечёткие оценки'!H18,'Нечёткие оценки'!H28) -> 1 | I6: =AVERAGE('Нечёткие оценки'!I8,'Нечёткие оценки'!I18,'Нечёткие оценки'!I28) -> 3.6666667 | J6: =MAX('Нечёткие оценки'!J8,'Нечёткие оценки'!J18,'Нечёткие оценки'!J28) -> 7 | K6: =MIN('Нечёткие оценки'!K8,'Нечёткие оценки'!K18,'Нечёткие оценки'!K28) -> 3 | L6: =AVERAGE('Нечёткие оценки'!L8,'Нечёткие оценки'!L18,'Нечёткие оценки'!L28) -> 5.6666667 | M6: =MAX('Нечёткие оценки'!M8,'Нечёткие оценки'!M18,'Нечёткие оценки'!M28) -> 9 | N6: =MIN('Нечёткие оценки'!N8,'Нечёткие оценки'!N18,'Нечёткие оценки'!N28) -> 3 | O6: =AVERAGE('Нечёткие оценки'!O8,'Нечёткие оценки'!O18,'Нечёткие оценки'!O28) -> 6.3333333 | P6: =MAX('Нечёткие оценки'!P8,'Нечёткие оценки'!P18,'Нечёткие оценки'!P28) -> 9
A7: AR-гид | B7: =MIN('Нечёткие оценки'!B9,'Нечёткие оценки'!B19,'Нечёткие оценки'!B29) -> 1 | C7: =AVERAGE('Нечёткие оценки'!C9,'Нечёткие оценки'!C19,'Нечёткие оценки'!C29) -> 1.6666667 | D7: =MAX('Нечёткие оценки'!D9,'Нечёткие оценки'!D19,'Нечёткие оценки'!D29) -> 5 | E7: =MIN('Нечёткие оценки'!E9,'Нечёткие оценки'!E19,'Нечёткие оценки'!E29) -> 3 | F7: =AVERAGE('Нечёткие оценки'!F9,'Нечёткие оценки'!F19,'Нечёткие оценки'!F29) -> 5.6666667 | G7: =MAX('Нечёткие оценки'!G9,'Нечёткие оценки'!G19,'Нечёткие оценки'!G29) -> 9 | H7: =MIN('Нечёткие оценки'!H9,'Нечёткие оценки'!H19,'Нечёткие оценки'!H29) -> 5 | I7: =AVERAGE('Нечёткие оценки'!I9,'Нечёткие оценки'!I19,'Нечёткие оценки'!I29) -> 7.6666667 | J7: =MAX('Нечёткие оценки'!J9,'Нечёткие оценки'!J19,'Нечёткие оценки'!J29) -> 9 | K7: =MIN('Нечёткие оценки'!K9,'Нечёткие оценки'!K19,'Нечёткие оценки'!K29) -> 1 | L7: =AVERAGE('Нечёткие оценки'!L9,'Нечёткие оценки'!L19,'Нечёткие оценки'!L29) -> 1.6666667 | M7: =MAX('Нечёткие оценки'!M9,'Нечёткие оценки'!M19,'Нечёткие оценки'!M29) -> 5 | N7: =MIN('Нечёткие оценки'!N9,'Нечёткие оценки'!N19,'Нечёткие оценки'!N29) -> 1 | O7: =AVERAGE('Нечёткие оценки'!O9,'Нечёткие оценки'!O19,'Нечёткие оценки'!O29) -> 2.3333333 | P7: =MAX('Нечёткие оценки'!P9,'Нечёткие оценки'!P19,'Нечёткие оценки'!P29) -> 5
A8: Рецепты | B8: =MIN('Нечёткие оценки'!B10,'Нечёткие оценки'!B20,'Нечёткие оценки'!B30) -> 5 | C8: =AVERAGE('Нечёткие оценки'!C10,'Нечёткие оценки'!C20,'Нечёткие оценки'!C30) -> 7.6666667 | D8: =MAX('Нечёткие оценки'!D10,'Нечёткие оценки'!D20,'Нечёткие оценки'!D30) -> 9 | E8: =MIN('Нечёткие оценки'!E10,'Нечёткие оценки'!E20,'Нечёткие оценки'!E30) -> 1 | F8: =AVERAGE('Нечёткие оценки'!F10,'Нечёткие оценки'!F20,'Нечёткие оценки'!F30) -> 3.6666667 | G8: =MAX('Нечёткие оценки'!G10,'Нечёткие оценки'!G20,'Нечёткие оценки'!G30) -> 7 | H8: =MIN('Нечёткие оценки'!H10,'Нечёткие оценки'!H20,'Нечёткие оценки'!H30) -> 1 | I8: =AVERAGE('Нечёткие оценки'!I10,'Нечёткие оценки'!I20,'Нечёткие оценки'!I30) -> 4.3333333 | J8: =MAX('Нечёткие оценки'!J10,'Нечёткие оценки'!J20,'Нечёткие оценки'!J30) -> 7 | K8: =MIN('Нечёткие оценки'!K10,'Нечёткие оценки'!K20,'Нечёткие оценки'!K30) -> 5 | L8: =AVERAGE('Нечёткие оценки'!L10,'Нечёткие оценки'!L20,'Нечёткие оценки'!L30) -> 7.6666667 | M8: =MAX('Нечёткие оценки'!M10,'Нечёткие оценки'!M20,'Нечёткие оценки'!M30) -> 9 | N8: =MIN('Нечёткие оценки'!N10,'Нечёткие оценки'!N20,'Нечёткие оценки'!N30) -> 3 | O8: =AVERAGE('Нечёткие оценки'!O10,'Нечёткие оценки'!O20,'Нечёткие оценки'!O30) -> 5.6666667 | P8: =MAX('Нечёткие оценки'!P10,'Нечёткие оценки'!P20,'Нечёткие оценки'!P30) -> 9
A9: Вес критерия | B9: =MIN('Нечёткие оценки'!B11,'Нечёткие оценки'!B21,'Нечёткие оценки'!B31) -> 5 | C9: =AVERAGE('Нечёткие оценки'!C11,'Нечёткие оценки'!C21,'Нечёткие оценки'!C31) -> 7.6666667 | D9: =MAX('Нечёткие оценки'!D11,'Нечёткие оценки'!D21,'Нечёткие оценки'!D31) -> 9 | E9: =MIN('Нечёткие оценки'!E11,'Нечёткие оценки'!E21,'Нечёткие оценки'!E31) -> 3 | F9: =AVERAGE('Нечёткие оценки'!F11,'Нечёткие оценки'!F21,'Нечёткие оценки'!F31) -> 5.6666667 | G9: =MAX('Нечёткие оценки'!G11,'Нечёткие оценки'!G21,'Нечёткие оценки'!G31) -> 9 | H9: =MIN('Нечёткие оценки'!H11,'Нечёткие оценки'!H21,'Нечёткие оценки'!H31) -> 1 | I9: =AVERAGE('Нечёткие оценки'!I11,'Нечёткие оценки'!I21,'Нечёткие оценки'!I31) -> 4.3333333 | J9: =MAX('Нечёткие оценки'!J11,'Нечёткие оценки'!J21,'Нечёткие оценки'!J31) -> 7 | K9: =MIN('Нечёткие оценки'!K11,'Нечёткие оценки'!K21,'Нечёткие оценки'!K31) -> 5 | L9: =AVERAGE('Нечёткие оценки'!L11,'Нечёткие оценки'!L21,'Нечёткие оценки'!L31) -> 7.6666667 | M9: =MAX('Нечёткие оценки'!M11,'Нечёткие оценки'!M21,'Нечёткие оценки'!M31) -> 9 | N9: =MIN('Нечёткие оценки'!N11,'Нечёткие оценки'!N21,'Нечёткие оценки'!N31) -> 5 | O9: =AVERAGE('Нечёткие оценки'!O11,'Нечёткие оценки'!O21,'Нечёткие оценки'!O31) -> 7.6666667 | P9: =MAX('Нечёткие оценки'!P11,'Нечёткие оценки'!P21,'Нечёткие оценки'!P31) -> 9
A11: Этап 3. Нормализация: r = (l/u*, m/u*, u/u*), u* — максимальное u по критерию
A12: Альтернатива | B12: Экономичность | E12: Актуальность | H12: Потенциал развития | K12: Простота реализации | N12: Соответствие компетенциям
B13: l | C13: m | D13: u | E13: l | F13: m | G13: u | H13: l | I13: m | J13: u | K13: l | L13: m | M13: u | N13: l | O13: m | P13: u
A14: Сплит | B14: =B4/MAX($D$4:$D$8) -> 0.55555556 | C14: =C4/MAX($D$4:$D$8) -> 0.85185185 | D14: =D4/MAX($D$4:$D$8) -> 1 | E14: =E4/MAX($G$4:$G$8) -> 0.33333333 | F14: =F4/MAX($G$4:$G$8) -> 0.7037037 | G14: =G4/MAX($G$4:$G$8) -> 1 | H14: =H4/MAX($J$4:$J$8) -> 0.33333333 | I14: =I4/MAX($J$4:$J$8) -> 0.62962963 | J14: =J4/MAX($J$4:$J$8) -> 1 | K14: =K4/MAX($M$4:$M$8) -> 0.55555556 | L14: =L4/MAX($M$4:$M$8) -> 0.85185185 | M14: =M4/MAX($M$4:$M$8) -> 1 | N14: =N4/MAX($P$4:$P$8) -> 0.55555556 | O14: =O4/MAX($P$4:$P$8) -> 0.92592593 | P14: =P4/MAX($P$4:$P$8) -> 1
A15: Репетиторы | B15: =B5/MAX($D$4:$D$8) -> 0.11111111 | C15: =C5/MAX($D$4:$D$8) -> 0.25925926 | D15: =D5/MAX($D$4:$D$8) -> 0.55555556 | E15: =E5/MAX($G$4:$G$8) -> 0.55555556 | F15: =F5/MAX($G$4:$G$8) -> 0.85185185 | G15: =G5/MAX($G$4:$G$8) -> 1 | H15: =H5/MAX($J$4:$J$8) -> 0.55555556 | I15: =I5/MAX($J$4:$J$8) -> 0.92592593 | J15: =J5/MAX($J$4:$J$8) -> 1 | K15: =K5/MAX($M$4:$M$8) -> 0.11111111 | L15: =L5/MAX($M$4:$M$8) -> 0.33333333 | M15: =M5/MAX($M$4:$M$8) -> 0.55555556 | N15: =N5/MAX($P$4:$P$8) -> 0.11111111 | O15: =O5/MAX($P$4:$P$8) -> 0.48148148 | P15: =P5/MAX($P$4:$P$8) -> 0.77777778
A16: Аудитории | B16: =B6/MAX($D$4:$D$8) -> 0.33333333 | C16: =C6/MAX($D$4:$D$8) -> 0.62962963 | D16: =D6/MAX($D$4:$D$8) -> 1 | E16: =E6/MAX($G$4:$G$8) -> 0.33333333 | F16: =F6/MAX($G$4:$G$8) -> 0.62962963 | G16: =G6/MAX($G$4:$G$8) -> 1 | H16: =H6/MAX($J$4:$J$8) -> 0.11111111 | I16: =I6/MAX($J$4:$J$8) -> 0.40740741 | J16: =J6/MAX($J$4:$J$8) -> 0.77777778 | K16: =K6/MAX($M$4:$M$8) -> 0.33333333 | L16: =L6/MAX($M$4:$M$8) -> 0.62962963 | M16: =M6/MAX($M$4:$M$8) -> 1 | N16: =N6/MAX($P$4:$P$8) -> 0.33333333 | O16: =O6/MAX($P$4:$P$8) -> 0.7037037 | P16: =P6/MAX($P$4:$P$8) -> 1
A17: AR-гид | B17: =B7/MAX($D$4:$D$8) -> 0.11111111 | C17: =C7/MAX($D$4:$D$8) -> 0.18518519 | D17: =D7/MAX($D$4:$D$8) -> 0.55555556 | E17: =E7/MAX($G$4:$G$8) -> 0.33333333 | F17: =F7/MAX($G$4:$G$8) -> 0.62962963 | G17: =G7/MAX($G$4:$G$8) -> 1 | H17: =H7/MAX($J$4:$J$8) -> 0.55555556 | I17: =I7/MAX($J$4:$J$8) -> 0.85185185 | J17: =J7/MAX($J$4:$J$8) -> 1 | K17: =K7/MAX($M$4:$M$8) -> 0.11111111 | L17: =L7/MAX($M$4:$M$8) -> 0.18518519 | M17: =M7/MAX($M$4:$M$8) -> 0.55555556 | N17: =N7/MAX($P$4:$P$8) -> 0.11111111 | O17: =O7/MAX($P$4:$P$8) -> 0.25925926 | P17: =P7/MAX($P$4:$P$8) -> 0.55555556
A18: Рецепты | B18: =B8/MAX($D$4:$D$8) -> 0.55555556 | C18: =C8/MAX($D$4:$D$8) -> 0.85185185 | D18: =D8/MAX($D$4:$D$8) -> 1 | E18: =E8/MAX($G$4:$G$8) -> 0.11111111 | F18: =F8/MAX($G$4:$G$8) -> 0.40740741 | G18: =G8/MAX($G$4:$G$8) -> 0.77777778 | H18: =H8/MAX($J$4:$J$8) -> 0.11111111 | I18: =I8/MAX($J$4:$J$8) -> 0.48148148 | J18: =J8/MAX($J$4:$J$8) -> 0.77777778 | K18: =K8/MAX($M$4:$M$8) -> 0.55555556 | L18: =L8/MAX($M$4:$M$8) -> 0.85185185 | M18: =M8/MAX($M$4:$M$8) -> 1 | N18: =N8/MAX($P$4:$P$8) -> 0.33333333 | O18: =O8/MAX($P$4:$P$8) -> 0.62962963 | P18: =P8/MAX($P$4:$P$8) -> 1
A20: Этап 4. Взвешенная нормализованная матрица v = r ⊗ w; идеальные решения A⁺ и A⁻
A21: Альтернатива | B21: Экономичность | E21: Актуальность | H21: Потенциал развития | K21: Простота реализации | N21: Соответствие компетенциям
B22: l | C22: m | D22: u | E22: l | F22: m | G22: u | H22: l | I22: m | J22: u | K22: l | L22: m | M22: u | N22: l | O22: m | P22: u
A23: Сплит | B23: =B14*B$9 -> 2.7777778 | C23: =C14*C$9 -> 6.5308642 | D23: =D14*D$9 -> 9 | E23: =E14*E$9 -> 1 | F23: =F14*F$9 -> 3.9876543 | G23: =G14*G$9 -> 9 | H23: =H14*H$9 -> 0.33333333 | I23: =I14*I$9 -> 2.7283951 | ... P23: =P14*P$9 -> 9
A24: Репетиторы | B24: =B15*B$9 -> 0.55555556 | C24: =C15*C$9 -> 1.9876543 | D24: =D15*D$9 -> 5 | E24: =E15*E$9 -> 1.6666667 | F24: =F15*F$9 -> 4.8271605 | G24: =G15*G$9 -> 9 | H24: =H15*H$9 -> 0.55555556 | I24: =I15*I$9 -> 4.0123457 | ... P24: =P15*P$9 -> 7
A25: Аудитории | B25: =B16*B$9 -> 1.6666667 | C25: =C16*C$9 -> 4.8271605 | D25: =D16*D$9 -> 9 | E25: =E16*E$9 -> 1 | F25: =F16*F$9 -> 3.5679012 | G25: =G16*G$9 -> 9 | H25: =H16*H$9 -> 0.11111111 | I25: =I16*I$9 -> 1.7654321 | ... P25: =P16*P$9 -> 9
A26: AR-гид | B26: =B17*B$9 -> 0.55555556 | C26: =C17*C$9 -> 1.4197531 | D26: =D17*D$9 -> 5 | E26: =E17*E$9 -> 1 | F26: =F17*F$9 -> 3.5679012 | G26: =G17*G$9 -> 9 | H26: =H17*H$9 -> 0.55555556 | I26: =I17*I$9 -> 3.691358 | ... P26: =P17*P$9 -> 5
A27: Рецепты | B27: =B18*B$9 -> 2.7777778 | C27: =C18*C$9 -> 6.5308642 | D27: =D18*D$9 -> 9 | E27: =E18*E$9 -> 0.33333333 | F27: =F18*F$9 -> 2.308642 | G27: =G18*G$9 -> 7 | H27: =H18*H$9 -> 0.11111111 | I27: =I18*I$9 -> 2.0864198 | ... P27: =P18*P$9 -> 9
A28: A⁺ (идеально позитивное) | B28: =MAX(B23:B27) -> 2.7777778 | C28: =MAX(C23:C27) -> 6.5308642 | D28: =MAX(D23:D27) -> 9 | E28: =MAX(E23:E27) -> 1.6666667 | F28: =MAX(F23:F27) -> 4.8271605 | G28: =MAX(G23:G27) -> 9 | H28: =MAX(H23:H27) -> 0.55555556 | I28: =MAX(I23:I27) -> 4.0123457 | ... P28: =MAX(P23:P27) -> 9
A29: A⁻ (идеально негативное) | B29: =MIN(B23:B27) -> 0.55555556 | C29: =MIN(C23:C27) -> 1.4197531 | D29: =MIN(D23:D27) -> 5 | E29: =MIN(E23:E27) -> 0.33333333 | F29: =MIN(F23:F27) -> 2.308642 | G29: =MIN(G23:G27) -> 7 | H29: =MIN(H23:H27) -> 0.11111111 | I29: =MIN(I23:I27) -> 1.7654321 | ... P29: =MIN(P23:P27) -> 5
A31: Этап 5. Расстояния до A⁺: d(x, y) = √(⅓·Σ(xₖ − yₖ)²), d⁺ — сумма по критериям
A32: Альтернатива | B32: Экономичность | E32: Актуальность | H32: Потенциал развития | K32: Простота реализации | N32: Соответствие компетенциям | Q32: d⁺
A33: Сплит | B33: =SQRT((1/3)*((B23-B$28)^2+(C23-C$28)^2+(D23-D$28)^2)) -> 0 | E33: =SQRT((1/3)*((E23-E$28)^2+(F23-F$28)^2+(G23-G$28)^2)) -> 0.61892785 | H33: =SQRT((1/3)*((H23-H$28)^2+(I23-I$28)^2+(J23-J$28)^2)) -> 0.7523102 | K33: =SQRT((1/3)*((K23-K$28)^2+(L23-L$28)^2+(M23-M$28)^2)) -> 0 | N33: =SQRT((1/3)*((N23-N$28)^2+(O23-O$28)^2+(P23-P$28)^2)) -> 0 | Q33: =SUM(B33,E33,H33,K33,N33) -> 1.3712381
A34: Репетиторы | B34: =SQRT((1/3)*((B24-B$28)^2+(C24-C$28)^2+(D24-D$28)^2)) -> 3.7228586 | E34: =SQRT((1/3)*((E24-E$28)^2+(F24-F$28)^2+(G24-G$28)^2)) -> 0 | H34: =SQRT((1/3)*((H24-H$28)^2+(I24-I$28)^2+(J24-J$28)^2)) -> 0 | K34: =SQRT((1/3)*((K24-K$28)^2+(L24-L$28)^2+(M24-M$28)^2)) -> 3.4995881 | N34: =SQRT((1/3)*((N24-N$28)^2+(O24-O$28)^2+(P24-P$28)^2)) -> 2.6171675 | Q34: =SUM(B34,E34,H34,K34,N34) -> 9.8396141
A35: Аудитории | B35: =SQRT((1/3)*((B25-B$28)^2+(C25-C$28)^2+(D25-D$28)^2)) -> 1.174333 | E35: =SQRT((1/3)*((E25-E$28)^2+(F25-F$28)^2+(G25-G$28)^2)) -> 0.82263364 | H35: =SQRT((1/3)*((H25-H$28)^2+(I25-I$28)^2+(J25-J$28)^2)) -> 1.5985311 | K35: =SQRT((1/3)*((K25-K$28)^2+(L25-L$28)^2+(M25-M$28)^2)) -> 1.174333 | N35: =SQRT((1/3)*((N25-N$28)^2+(O25-O$28)^2+(P25-P$28)^2)) -> 1.174333 | Q35: =SUM(B35,E35,H35,K35,N35) -> 5.9441638
A36: AR-гид | B36: =SQRT((1/3)*((B26-B$28)^2+(C26-C$28)^2+(D26-D$28)^2)) -> 3.9607124 | E36: =SQRT((1/3)*((E26-E$28)^2+(F26-F$28)^2+(G26-G$28)^2)) -> 0.82263364 | H36: =SQRT((1/3)*((H26-H$28)^2+(I26-I$28)^2+(J26-J$28)^2)) -> 0.18532231 | K36: =SQRT((1/3)*((K26-K$28)^2+(L26-L$28)^2+(M26-M$28)^2)) -> 3.9607124 | N36: =SQRT((1/3)*((N26-N$28)^2+(O26-O$28)^2+(P26-P$28)^2)) -> 3.9607124 | Q36: =SUM(B36,E36,H36,K36,N36) -> 12.890093
A37: Рецепты | B37: =SQRT((1/3)*((B27-B$28)^2+(C27-C$28)^2+(D27-D$28)^2)) -> 0 | E37: =SQRT((1/3)*((E27-E$28)^2+(F27-F$28)^2+(G27-G$28)^2)) -> 2.0100343 | H37: =SQRT((1/3)*((H27-H$28)^2+(I27-I$28)^2+(J27-J$28)^2)) -> 1.4521794 | K37: =SQRT((1/3)*((K27-K$28)^2+(L27-L$28)^2+(M27-M$28)^2)) -> 0 | N37: =SQRT((1/3)*((N27-N$28)^2+(O27-O$28)^2+(P27-P$28)^2)) -> 1.4599951 | Q37: =SUM(B37,E37,H37,K37,N37) -> 4.9222087
A39: Этап 5 (продолжение). Расстояния до A⁻
A40: Альтернатива | B40: Экономичность | E40: Актуальность | H40: Потенциал развития | K40: Простота реализации | N40: Соответствие компетенциям | Q40: d⁻
A41: Сплит | B41: =SQRT((1/3)*((B23-B$29)^2+(C23-C$29)^2+(D23-D$29)^2)) -> 3.9607124 | E41: =SQRT((1/3)*((E23-E$29)^2+(F23-F$29)^2+(G23-G$29)^2)) -> 1.5560127 | H41: =SQRT((1/3)*((H23-H$29)^2+(I23-I$29)^2+(J23-J$29)^2)) -> 1.0640228 | K41: =SQRT((1/3)*((K23-K$29)^2+(L23-L$29)^2+(M23-M$29)^2)) -> 3.9607124 | N41: =SQRT((1/3)*((N23-N$29)^2+(O23-O$29)^2+(P23-P$29)^2)) -> 3.9607124 | Q41: =SUM(B41,E41,H41,K41,N41) -> 14.502173
A42: Репетиторы | B42: =SQRT((1/3)*((B24-B$29)^2+(C24-C$29)^2+(D24-D$29)^2)) -> 0.32787793 | E42: =SQRT((1/3)*((E24-E$29)^2+(F24-F$29)^2+(G24-G$29)^2)) -> 2.0100343 | H42: =SQRT((1/3)*((H24-H$29)^2+(I24-I$29)^2+(J24-J$29)^2)) -> 1.5985311 | K42: =SQRT((1/3)*((K24-K$29)^2+(L24-L$29)^2+(M24-M$29)^2)) -> 0.65575586 | N42: =SQRT((1/3)*((N24-N$29)^2+(O24-O$29)^2+(P24-P$29)^2)) -> 1.5168615 | Q42: =SUM(B42,E42,H42,K42,N42) -> 6.1090606
A43: Аудитории | B43: =SQRT((1/3)*((B25-B$29)^2+(C25-C$29)^2+(D25-D$29)^2)) -> 3.100806 | E43: =SQRT((1/3)*((E25-E$29)^2+(F25-F$29)^2+(G25-G$29)^2)) -> 1.4177657 | H43: =SQRT((1/3)*((H25-H$29)^2+(I25-I$29)^2+(J25-J$29)^2)) -> 0 | K43: =SQRT((1/3)*((K25-K$29)^2+(L25-L$29)^2+(M25-M$29)^2)) -> 3.100806 | N43: =SQRT((1/3)*((N25-N$29)^2+(O25-O$29)^2+(P25-P$29)^2)) -> 3.100806 | Q43: =SUM(B43,E43,H43,K43,N43) -> 10.720184
A44: AR-гид | B44: =SQRT((1/3)*((B26-B$29)^2+(C26-C$29)^2+(D26-D$29)^2)) -> 0 | E44: =SQRT((1/3)*((E26-E$29)^2+(F26-F$29)^2+(G26-G$29)^2)) -> 1.4177657 | H44: =SQRT((1/3)*((H26-H$29)^2+(I26-I$29)^2+(J26-J$29)^2)) -> 1.4521794 | K44: =SQRT((1/3)*((K26-K$29)^2+(L26-L$29)^2+(M26-M$29)^2)) -> 0 | N44: =SQRT((1/3)*((N26-N$29)^2+(O26-O$29)^2+(P26-P$29)^2)) -> 0 | Q44: =SUM(B44,E44,H44,K44,N44) -> 2.869945
...

Sheet Итог
A1: Этап 6. Коэффициент относительной близости CCᵢ = d⁻ / (d⁺ + d⁻)
A3: Альтернатива | B3: d⁺ | C3: d⁻ | D3: CCᵢ | E3: Ранг
A4: Сплит | B4: =Расчёт!Q33 -> 1.3712381 | C4: =Расчёт!Q41 -> 14.502173 | D4: =C4/(B4+C4) -> 0.91361415 | E4: =RANK(D4,$D$4:$D$8,0) -> 1
A5: Репетиторы | B5: =Расчёт!Q34 -> 9.8396141 | C5: =Расчёт!Q42 -> 6.1090606 | D5: =C5/(B5+C5) -> 0.38304503 | E5: =RANK(D5,$D$4:$D$8,0) -> 4
A6: Аудитории | B6: =Расчёт!Q35 -> 5.9441638 | C6: =Расчёт!Q43 -> 10.720184 | D6: =C6/(B6+C6) -> 0.64330054 | E6: =RANK(D6,$D$4:$D$8,0) -> 3
A7: AR-гид | B7: =Расчёт!Q36 -> 12.890093 | C7: =Расчёт!Q44 -> 2.869945 | D7: =C7/(B7+C7) -> 0.18210267 | E7: =RANK(D7,$D$4:$D$8,0) -> 5
A8: Рецепты | B8: =Расчёт!Q37 -> 4.9222087 | C8: =Расчёт!Q45 -> 11.010616 | D8: =C8/(B8+C8) -> 0.69106491 | E8: =RANK(D8,$D$4:$D$8,0) -> 2
A10: Лучшая концепция | B10: =INDEX($A$4:$A$8,MATCH(MAX($D$4:$D$8),$D$4:$D$8,0)) -> Сплит
A12: Чем ближе CCᵢ к 1, тем ближе альтернатива к идеально позитивному решению и дальше от идеально негативного.
